Workbook

Sheet Data
A1: 1 | B1: abc | C1: x | D1: 10 | F1: Name | G1: Qty | H1: Price
A2: 2 | B2: 10 | C2: y | D2: 20 | F2: pen | G2: 3 | H2: 1.5
A3: 3 | B3: TRUE | C3: z | D3: 30 | F3: book | G3: 1 | H3: 12
A4: 4 | C4: x | D4: 40 | F4: ink | G4: 5 | H4: 4.25
A5: 5 | B5: =NA() -> #N/A | C5: w | D5: 50
A6: 6 | B6: 2.5
A7: 7 | B7: -3
A8: 8 | B8: Apple
A9: 9 | B9: apple
A10: 10 | B10: 43845

Sheet About
A1: 16.0 20326
A2: 46288

Sheet Numbers
A1: 0
A2: 1
A3: -1
A4: 0.5
A5: 1.5
A6: 2.5
A7: -2.5
A8: 0.1
A9: 0.2
A10: 0.3
A11: 0.3
A12: 0.33333333
... A190: -123.456

Sheet Pairs
A1: 1 | B1: 1
A2: 1 | B2: 1
A3: 1 | B3: 1
A4: 1 | B4: 1
A5: 1 | B5: 1
A6: 1 | B6: 1
A7: 1 | B7: 1
A8: 1 | B8: 1
A9: 1 | B9: 1
A10: 1 | B10: 1
A11: 1 | B11: 1
A12: 1 | B12: 1
... A322: 1e+300 | B322: 1e+300

Sheet FileLiterals
A1: =1.23456789012345 -> 1.2345679
A2: =2.99999999999999 -> 3
A3: =0.3 -> 0.3
A4: =1234567890123450000 -> 1.2345679e+18
A5: =1234567890123450 -> 1.2345679e+15
A6: =1234567890123450 -> 1.2345679e+15
A7: =0.1+0.2 -> 0.3

Sheet Powers
A1: 90.41396 | B1: 1.3804108
A2: 36.11932 | B2: 3.3182261
A3: 0.78008616 | B3: -3.3963828
A4: 64.497089 | B4: 0.15497852
A5: 6.5393755 | B5: 1.8534908
A6: 60.537048 | B6: 1.3612429
A7: 85.256483 | B7: 1.501425
A8: 51.52145 | B8: -2.2714049
A9: 86.229816 | B9: 0.17340689
A10: 10.810846 | B10: 1.350468
A11: 20.48873 | B11: -2.6253909
A12: 93.792005 | B12: 3.6125676
... A654: 2 | B654: 10.5

Sheet Rounding
A1: 2.675 | B1: 2
A2: 2.675 | B2: 2
A3: 2.675 | B3: 2
A4: 2.675 | B4: 2
A5: 2.675 | B5: 2
A6: 1.005 | B6: 2
A7: 1.005 | B7: 2
A8: 1.005 | B8: 2
A9: 1.005 | B9: 2
A10: 1.005 | B10: 2
A11: 0.285 | B11: 2
A12: 0.285 | B12: 2
... A130: 0.3 | B130: 20

Sheet Divisions
A1: 10 | B1: 3.3
A2: 5.5 | B2: 2
A3: 10000000000 | B3: 3
A4: 134217728 | B4: 3
A5: 150000000 | B5: 7
A6: 1 | B6: 0.1
A7: 0.3 | B7: 0.1
A8: 7 | B8: 0.7
A9: -7 | B9: 0.7
A10: 7 | B10: -0.7
A11: 1e+15 | B11: 7
A12: 2.5e+15 | B12: 3
... A28: 11 | B28: 2.2

Sheet DatePairs
A1: 43861 | B1: 43890
A2: 43890 | B2: 43921
A3: 43524 | B3: 43555
A4: 43860 | B4: 43921
A5: 43921 | B5: 44285
A6: 43831 | B6: 44196
A7: 43631 | B7: 44255
A8: 43524 | B8: 43890
A9: 43890 | B9: 44255
A10: 44255 | B10: 44286
A11: 43982 | B11: 44074
A12: 43981 | B12: 44074
... A18: 43830 | B18: 43891

Sheet Reals
A1: -6.1527241
A2: -4.263151
A3: -7.6368943
A4: -3.8741616
A5: -3.813126
A6: -6.3111441
A7: 1.379728
A8: 4.7139959
A9: -5.8913345
A10: 0.19989827
A11: -6.9018988
A12: 9.5075696
... A72: 10000000

Sheet Wholes
A1: 3
A2: 3
A3: 3
A4: 3
A5: 3
A6: 3
A7: 3
A8: 3
A9: 3
A10: -3
A11: -3
A12: -3
... A90: 3.3

Sheet Times
A1: 0.5
A2: 0.49999537
A3: 0.49999421
A4: 0.49999306
A5: 0.50000463
A6: 0.50000579
A7: 0.75
A8: 0.74999537
A9: 0.74999421
A10: 0.74999306
A11: 0.75000463
A12: 0.75000579
... A54: 1.5000058

Sheet Ties
A1: 1.2345679e+15
A2: 1.2345679e+15
A3: 1.2345679e+15
A4: 1.2345679e+15
A5: 1e+15
A6: 1e+16
A7: 9.0071993e+15
A8: 1.1258999e+15

Sheet Crit
A1: 10 | B1: 1
A2: 10 | B2: 2
A3: 10.0 | B3: 3
A4: abc | B4: 4
A5: Apple | B5: 5
A6: apple | B6: 6
A7: ß | B7: 7
A8: ss | B8: 8
A9: SS | B9: 9
A10: æ | B10: 10
A11: ae | B11: 11
A12: é | B12: 12
A13: e | B13: 13
A14: TRUE | B14: 14
A15: FALSE | B15: 15
A16: TRUE | B16: 16
A17: =NA() -> #N/A | B17: 17
A18: ="" | B18: 18
B19: 19
A20: 5 | B20: 20
A21: 5 | B21: 21
A22: 43832 | B22: 22
A23: 43832 | B23: 23
A24: * | B24: 24
A25: a*e | B25: 25
A26: 10 | B26: 26
A27: 0 | B27: 27
A28: -1 | B28: 28
A29: 0.5 | B29: 29
A30: 1/2/2020 | B30: 30

Sheet Stats
A1: 0.774 | B1: 4.194 | C1: 1.3342 | D1: 20 | E1: 5 | F1: 1
A2: 1.767 | B2: 5.441 | C2: 1.7517 | D2: 40 | E2: 7 | F2: =1/0 -> #DIV/0!
A3: 2.866 | B3: 10.794 | C3: 2.1294 | D3: 60 | E3: =SUBTOTAL(9,E1:E2) -> 12 | F3: 3
A4: 3.603 | B4: 13.045 | C4: 2.7647 | E4: 11 | F4: x
A5: 4.826 | B5: 13.776 | C5: 3.6061 | F5: 5
A6: 5.71 | B6: 15.822 | C6: 4.7191
A7: 7.335 | B7: 22.329 | C7: 6.0413
A8: 7.675 | B8: 23.196 | C8: 7.8058
A9: 9.293 | B9: 24.59 | C9: 10.2991
A10: 9.684 | B10: 26.568 | C10: 13.1682
A11: 10.792 | B11: 30.664 | E11: 30
A12: 11.894 | B12: 34.612 | E12: 50
A13: 12.838 | B13: 33.265 | E13: 70
A14: 13.849 | B14: 38.817
A15: 14.631 | B15: 39.9
A16: 15.619 | B16: 43.917
A17: 17.379 | B17: 45.848
A18: 17.712 | B18: 48.838
A19: 18.868 | B19: 49.288
A20: 19.964 | B20: 54.442

Sheet Db
A1: Tree | B1: Height | C1: Age | D1: Yield | E1: Profit | G1: Tree | H1: Height | J1: Height | L1: Rich | M1: Tree | O1: Tree
A2: Apple | B2: 18 | C2: 20 | D2: 14 | E2: 105 | G2: Apple | H2: >10 | J2: =12 | L2: =E2>80 -> TRUE | M2: <>Plum | O2: P*
A3: Pear | B3: 12 | C3: 12 | D3: 10 | E3: 96 | G3: Pear
A4: Cherry | B4: 13 | C4: 14 | D4: 9 | E4: 105
A5: Apple | B5: 14 | C5: 15 | D5: 10 | E5: 75
A6: Pear | B6: 9 | C6: 8 | D6: 8 | E6: 76.8
A7: Apple | B7: 8 | C7: 9 | D7: 6 | E7: 45
A8: Cherry | B8: 10 | C8: 10 | D8: 7 | E8: 60
A9: Apple | B9: 11 | C9: 13 | D9: 9 | E9: 66
A10: Pear | B10: 7 | C10: 6 | D10: 5 | E10: 40
A11: Plum | B11: 15 | C11: 11 | D11: 12 | E11: 90

Sheet Samples
A1: V1 | B1: V2 | C1: V3 | D1: V4 | E1: V5 | F1: V6 | G1: V7 | H1: V8 | I1: V9 | J1: V10 | L1: V1
A2: 0.277007 | B2: 0.050447 | C2: 9671.1275 | D2: 17.300559 | E2: 18.420596 | F2: 69.802701 | G2: 15772.901 | H2: 0.096232 | I2: 59389.263 | J2: 6722.6976 | L2: >0
A3: 0.102698 | B3: 0.066709 | C3: 3064.0661 | D3: 54.406813 | E3: 31.904589 | F3: 86.737231 | G3: 82404.336 | H3: 0.582581 | I3: 32168.352 | J3: 4945.0131
A4: 0.569885 | B4: 0.033721 | C4: 5725.0288 | D4: 42.826947 | E4: 91.486429 | F4: 78.19125 | G4: 19696.902 | H4: 0.491159 | I4: 50493.661 | J4: 7811.1827
A5: 0.605697 | B5: 0.047536 | C5: 6812.3225 | D5: 98.579979 | E5: 10.699521 | F5: 13.170342 | G5: 84403.801 | H5: 0.660397 | I5: 16639.073 | J5: 4764.5823
A6: 0.511476 | B6: 0.089766 | C6: 6582.0719 | D6: 94.721315 | E6: 27.198858 | F6: 22.830991 | G6: 26433.141 | H6: 0.35419 | I6: 85902.902 | J6: 6985.6876
A7: 0.172647 | B7: 0.054964 | C7: 2901.5364 | D7: 30.803282 | E7: 28.386658 | F7: 48.817541 | G7: 89127.316 | H7: 0.088656 | I7: 23940.729 | J7: 3909.5037
A8: 0.612202 | B8: 0.020838 | C8: 6855.18 | D8: 81.212086 | E8: 77.953456 | F8: 69.994602 | G8: 68145.613 | H8: 0.099158 | I8: 62552.493 | J8: 335.71354
A9: 0.039278 | B9: 0.088915 | C9: 5709.4843 | D9: 12.375188 | E9: 63.002592 | F9: 73.445134 | G9: 26481.624 | H9: 0.531974 | I9: 3188.7372 | J9: 3994.9342
A10: 0.50332 | B10: 0.028635 | C10: 1646.4751 | D10: 40.871636 | E10: 12.013873 | F10: 40.244179 | G10: 70360.231 | H10: 0.328308 | I10: 7006.2965 | J10: 988.20693
A11: 0.58955 | B11: 0.026547 | C11: 1454.4351 | D11: 51.508417 | E11: 88.593603 | F11: 70.315853 | G11: 91300.36 | H11: 0.441738 | I11: 92141.498 | J11: 2441.6402
A12: 0.188819 | B12: 0.050507 | C12: 359.57282 | D12: 84.358775 | E12: 3.692175 | F12: 68.088568 | G12: 96347.277 | H12: 0.606893 | I12: 95347.824 | J12: 4677.3097
A13: 0.798492 | B13: 0.061543 | C13: 7297.8422 | D13: 34.745438 | E13: 3.748554 | F13: 77.101358 | G13: 49656.413 | H13: 0.803851 | I13: 24353.172 | J13: 4163.3574

Sheet Operators
A1: =1+2*3 -> 7
A2: =(1+2)*3 -> 9
A3: =-2^2 -> 4
A4: =2^3^2 -> 64
A5: =-(2^2) -> -4
A6: =2^-1 -> 0.5
A7: =10/4 -> 2.5
A8: =1/0 -> #DIV/0!
A9: =0/0 -> #DIV/0!
A10: =7% -> 0.07
A11: =50%*2 -> 1
A12: =5%% -> 0.0005
A13: =-(-3) -> 3
A14: =3 -> 3
A15: =--3 -> 3
A17: =1-2-3 -> -4
A18: =12/3/2 -> 2
A19: =2*3^2 -> 18
A20: =(2*3)^2 -> 36
A21: =0.1+0.2 -> 0.3
A22: =0.1+0.2-0.3 -> 0
A23: =1-0.9-0.1 -> 0
A24: =(0.1+0.2)-0.3 -> 0
A25: =0.3-0.2-0.1 -> 0
A26: =1*(0.5-0.4-0.1) -> -2.7755576e-17
A28: =2^1024 -> #NUM!
A29: =2^1023 -> 8.9884657e+307
A30: =-2^0.5 -> #NUM!
A31: =(-8)^(1/3) -> -2
A32: =0^0 -> #NUM!
A33: =0^-1 -> #DIV/0!
A34: =10^-400 -> 0
A35: =1&2 -> 12
A36: =1.5&"" -> 1.5
A37: =(0.1+0.2)&"" -> 0.3
A38: =TRUE&"" -> TRUE
A39: =FALSE&1 -> FALSE1
A40: =100000000000000000000&"" -> 1E+20
A41: =123456789012&"" -> 123456789012
A42: =1234567890123450&"" -> 1234567890123450
...

Sheet Compare
A1: =1<2 -> TRUE
A2: =2<1 -> FALSE
A3: =1=1 -> TRUE
A4: =1<>1 -> FALSE
A5: =1<"a" -> TRUE
A6: ="a"<TRUE -> TRUE
A7: =1<TRUE -> TRUE
A8: ="a"="A" -> TRUE
A9: ="a"<"B" -> TRUE
A10: ="B"<"a" -> FALSE
A11: ="10"<"9" -> TRUE
A12: =10<9 -> FALSE
A13: ="apple"<"Apple" -> FALSE
A14: ="Apple"<"apple" -> FALSE
A15: ="apple"="Apple" -> TRUE
A16: =Data!B4=0 -> TRUE
A17: =Data!B4="" -> TRUE
A18: =Data!B4=FALSE -> TRUE
A19: =Data!B4<1 -> TRUE
A20: =Data!B4>-1 -> TRUE
A21: =Data!B4<"a" -> TRUE
A22: =""<"a" -> TRUE
A23: =""=0 -> FALSE
A24: =0=FALSE -> FALSE
A25: =1=TRUE -> FALSE
A26: ="1"=1 -> FALSE
A27: =Data!B2=10 -> FALSE
A28: =Data!B2="10" -> TRUE
A29: =TRUE>FALSE -> TRUE
A30: ="z"<"aa" -> FALSE
A31: ="a b"<"ab" -> TRUE
A32: ="a-b"<"ab" -> FALSE
A33: ="é"<"f" -> TRUE
A34: ="e"<"é" -> TRUE
A35: ="ß"="ss" -> TRUE
A36: =#N/A=1 -> #N/A
A37: =1=#N/A -> #N/A
A38: =0.1+0.2=0.3 -> TRUE
A39: =1/3*3=1 -> TRUE
A40: ="a"<="A" -> TRUE
...

Sheet Math
A1: =ROUND(2.5,0) -> 3
A2: =ROUND(-2.5,0) -> -3
A3: =ROUND(2.45,1) -> 2.5
A4: =ROUND(1.005,2) -> 1.01
A5: =ROUND(1234.5678,-2) -> 1200
A6: =ROUND(0.285,2) -> 0.29
A7: =ROUNDUP(3.14159,2) -> 3.15
A8: =ROUNDUP(-3.14159,2) -> -3.15
A9: =ROUNDDOWN(3.99,0) -> 3
A10: =ROUNDDOWN(-3.99,0) -> -3
A11: =INT(3.7) -> 3
A12: =INT(-3.2) -> -4
A13: =TRUNC(-3.7) -> -3
A14: =TRUNC(3.14159,3) -> 3.141
A15: =MOD(5,3) -> 2
A16: =MOD(-5,3) -> 1
A17: =MOD(5,-3) -> -1
A18: =MOD(-5,-3) -> -2
A19: =MOD(5.5,2) -> 1.5
A20: =MOD(5,0) -> #DIV/0!
A21: =ABS(-4.5) -> 4.5
A22: =SIGN(-2) -> -1
A23: =SIGN(0) -> 0
A24: =SQRT(16) -> 4
A25: =SQRT(-1) -> #NUM!
A26: =POWER(2,10) -> 1024
A27: =POWER(-8,1/3) -> -2
A28: =EXP(1) -> 2.7182818
A29: =LN(10) -> 2.3025851
A30: =LOG(100) -> 2
A31: =LOG(8,2) -> 3
A32: =LOG10(1000) -> 3
A33: =LN(0) -> #NUM!
A34: =PI() -> 3.1415927
A35: =CEILING(4.3,1) -> 5
A36: =CEILING(-4.3,-1) -> -5
A37: =CEILING(4.3,0.5) -> 4.5
A38: =FLOOR(4.7,1) -> 4
A39: =FLOOR(-4.7,-1) -> -4
A40: =_xlfn.CEILING.MATH(-4.3) -> -4
...

Sheet Aggregate
A1: =AVERAGE(Data!A1:A10) -> 5.5
A2: =AVERAGE(1,"2",TRUE) -> 1.3333333
A3: =AVERAGE(Data!B1:B4) -> #DIV/0!
A4: =AVERAGEA(Data!B1:B4) -> 0.33333333
A5: =MIN(Data!A1:A10) -> 1
A6: =MAX(Data!A1:A10) -> 10
A7: =MIN(Data!B1:B4) -> 0
A8: =MAX(Data!B1:B4) -> 0
A9: =MIN("3",5) -> 3
A10: =MAX(Data!B6:B7) -> 2.5
A11: =MINA(Data!B1:B4) -> 0
A12: =MAXA(Data!B1:B4) -> 1
A13: =COUNT(Data!A1:B10) -> 13
A14: =COUNT(1,"2",TRUE,"x") -> 3
A15: =COUNTA(Data!B1:B10) -> 9
A16: =COUNTBLANK(Data!B1:B10) -> 1
A17: =MEDIAN(1,3,2,4) -> 2.5
A18: =MEDIAN(Data!A1:A10) -> 5.5
A19: =MODE(1,2,2,3) -> 2
A20: =LARGE(Data!A1:A10,2) -> 9
A21: =SMALL(Data!A1:A10,3) -> 3
A22: =LARGE(Data!A1:A10,11) -> #NUM!
A23: =STDEV(Data!A1:A10) -> 3.0276504
A24: =STDEVP(Data!A1:A10) -> 2.8722813
A25: =VAR(Data!A1:A10) -> 9.1666667
A26: =VARP(Data!A1:A10) -> 8.25
A27: =_xlfn.STDEV.S(2,4,4,4,5,5,7,9) -> 2.1380899
A28: =_xlfn.STDEV.P(2,4,4,4,5,5,7,9) -> 2
A29: =RANK(3,Data!A1:A10) -> 8
A30: =RANK(3,Data!A1:A10,1) -> 3
A31: =AVERAGE(Data!B1) -> #DIV/0!
A32: =MAX(Data!B5:B6) -> #N/A
A33: =COUNT(Data!B5) -> 0

Sheet Conditional
A1: =SUMIF(Data!A1:A10,">5") -> 40
A2: =SUMIF(Data!C1:C5,"x",Data!D1:D5) -> 50
A3: =SUMIF(Data!C1:C5,"<>x",Data!D1:D5) -> 100
A4: =COUNTIF(Data!A1:A10,">=3") -> 8
A5: =COUNTIF(Data!C1:C5,"x") -> 2
A6: =COUNTIF(Data!B1:B10,"apple") -> 2
A7: =COUNTIF(Data!B1:B10,"a*") -> 3
A8: =COUNTIF(Data!B1:B10,"?pple") -> 2
A9: =COUNTIF(Data!B1:B10,"*") -> 4
A10: =COUNTIF(Data!B1:B10,"<>") -> 9
A11: =COUNTIF(Data!B1:B10,"") -> 1
A12: =COUNTIF(Data!B1:B10,10) -> 1
A13: =COUNTIF(Data!B1:B10,"10") -> 1
A14: =COUNTIF(Data!B1:B10,TRUE) -> 1
A15: =COUNTIF(Data!A1:A10,"<5") -> 4
A16: =COUNTIF(Data!A1:A10,"=5") -> 1
A17: =COUNTIF(Data!A1:A10,5) -> 1
A18: =COUNTIF(Data!A1:A10,"5") -> 1
A19: =AVERAGEIF(Data!A1:A10,">5") -> 8
A20: =AVERAGEIF(Data!C1:C5,"x",Data!D1:D5) -> 25
A21: =SUMIFS(Data!D1:D5,Data!C1:C5,"x",Data!D1:D5,">15") -> 40
A22: =COUNTIFS(Data!C1:C5,"x",Data!D1:D5,">15") -> 1
A23: =AVERAGEIFS(Data!D1:D5,Data!C1:C5,"<>y") -> 32.5
A24: =_xlfn.MAXIFS(Data!D1:D5,Data!C1:C5,"x") -> 40
A25: =_xlfn.MINIFS(Data!D1:D5,Data!C1:C5,"x") -> 10
A26: =COUNTIF(Data!C1:C5,"~*") -> 0
A27: =SUMIF(Data!A1:A10,">"&5) -> 40
A28: =COUNTIF(Data!B1:B10,">b") -> 0
A29: =COUNTIF(Data!B1:B10,"<b") -> 4
A30: =AVERAGEIF(Data!C1:C5,"q",Data!D1:D5) -> #DIV/0!

Sheet Logic
A1: =IF(1>0,"yes","no") -> yes
A2: =IF(0,"yes","no") -> no
A3: =IF("TRUE",1,2) -> 1
A4: =IF("x",1,2) -> #VALUE!
A5: =IF(1,,2) -> 0
A6: =IF(0,1) -> FALSE
A7: =IF(Data!B4,1,2) -> 2
A8: =AND(TRUE,1,"TRUE") -> TRUE
A9: =AND(TRUE,0) -> FALSE
A10: =OR(FALSE,0) -> FALSE
A11: =OR(Data!B1:B4) -> TRUE
A12: =AND(Data!B1) -> #VALUE!
A13: =NOT(0) -> TRUE
A14: =NOT("FALSE") -> TRUE
A15: =_xlfn.XOR(TRUE,TRUE,TRUE) -> TRUE
A16: =IFERROR(1/0,"div") -> div
A17: =IFERROR(5,"x") -> 5
A18: =_xlfn.IFNA(Data!B5,"na") -> na
A19: =_xlfn.IFNA(1/0,"na") -> #DIV/0!
A20: =_xlfn.IFS(1>2,"a",2>1,"b") -> b
A21: =_xlfn.IFS(1>2,"a") -> #N/A
A22: =_xlfn.SWITCH(2,1,"one",2,"two","other") -> two
A23: =_xlfn.SWITCH(9,1,"one","other") -> other
A24: =_xlfn.SWITCH(9,1,"one") -> #N/A
A25: =CHOOSE(2,"a","b","c") -> b
A26: =CHOOSE(4,"a","b","c") -> #VALUE!
A27: =CHOOSE(2.9,"a","b","c") -> b
A28: =TRUE() -> TRUE
A29: =FALSE() -> FALSE
A30: =IF(1/0>1,1,2) -> #DIV/0!
A31: =IF(TRUE,1/0,2) -> #DIV/0!

Sheet Text
A1: =LEFT("hello",2) -> he
A2: =LEFT("hello") -> h
A3: =RIGHT("hello",3) -> llo
A4: =MID("hello",2,3) -> ell
A5: =MID("hello",9,2)
A6: =MID("hello",0,2) -> #VALUE!
A7: =LEN("hello") -> 5
A8: =LEN(1234.5) -> 6
A9: =LEN(Data!B4) -> 0
A10: =LEN(TRUE) -> 4
A11: =UPPER("Mixed Case") -> MIXED CASE
A12: =LOWER("Mixed Case") -> mixed case
A13: =PROPER("hello wORLD o'neil") -> Hello World O'Neil
A14: =TRIM(" a b ") -> a b
A15: =FIND("l","hello") -> 3
A16: =FIND("L","hello") -> #VALUE!
A17: =SEARCH("L","hello") -> 3
A18: =SEARCH("l?o","hello") -> 3
A19: =SEARCH("e*o","hello") -> 2
A20: =FIND("l","hello",4) -> 4
A21: =SUBSTITUTE("a-b-c","-","+") -> a+b+c
A22: =SUBSTITUTE("a-b-c","-","+",2) -> a-b+c
A23: =REPLACE("abcdef",2,3,"X") -> aXef
A24: =CONCATENATE("a",1,TRUE) -> a1TRUE
A25: =_xlfn.CONCAT("a",Data!A1:A3) -> a123
A26: =_xlfn.TEXTJOIN(",",TRUE,Data!B1:B4) -> abc,10,TRUE
A27: =_xlfn.TEXTJOIN(",",FALSE,Data!B1:B4) -> abc,10,TRUE,
A28: =REPT("ab",3) -> ababab
A29: =EXACT("a","A") -> FALSE
A30: =EXACT("a","a") -> TRUE
A31: =TEXT(1234.567,"#,##0.00") -> 1,234.57
A32: =TEXT(0.25,"0%") -> 25%
A33: =TEXT(Data!B10,"yyyy-mm-dd") -> 2020-01-15
A34: =TEXT(-5,"0;(0)") -> (5)
A35: =VALUE("12.5") -> 12.5
A36: =VALUE("abc") -> #VALUE!
A37: =VALUE("1,234") -> 1234
A38: =VALUE("25%") -> 0.25
A39: =CHAR(65) -> A
A40: =CODE("A") -> 65
...

Sheet Info
A1: =ISBLANK(Data!B4) -> TRUE
A2: =ISBLANK(Data!B1) -> FALSE
A3: =ISNUMBER(Data!B2) -> FALSE
A4: =ISNUMBER(Data!A1) -> TRUE
A5: =ISTEXT(Data!B2) -> TRUE
A6: =ISTEXT(Data!B4) -> FALSE
A7: =ISLOGICAL(Data!B3) -> TRUE
A8: =ISERROR(Data!B5) -> TRUE
A9: =ISERR(Data!B5) -> FALSE
A10: =ISNA(Data!B5) -> TRUE
A11: =ISERR(1/0) -> TRUE
A12: =ISNONTEXT(Data!B4) -> TRUE
A13: =ISEVEN(4) -> TRUE
A14: =ISODD(4) -> FALSE
A15: =TYPE(1) -> 1
A16: =TYPE("a") -> 2
A17: =TYPE(TRUE) -> 4
A18: =TYPE(1/0) -> 16
A19: =TYPE(Data!B4) -> 1
A20: =NA() -> #N/A
A21: =ERROR.TYPE(1/0) -> 2
A22: =ERROR.TYPE(Data!B5) -> 7
A23: =ROW(Data!C3) -> 3
A24: =COLUMN(Data!C3) -> 3
A25: =ROWS(Data!A1:B4) -> 4
A26: =COLUMNS(Data!A1:B4) -> 2
A27: =ISREF(Data!A1) -> TRUE
A28: =_xlfn.ISFORMULA(Data!B5) -> TRUE
A29: =_xlfn.ISFORMULA(Data!B1) -> FALSE

Sheet Lookup
A1: =VLOOKUP("book",Data!F2:H4,3,FALSE) -> 12
A2: =VLOOKUP("BOOK",Data!F2:H4,2,FALSE) -> 1
A3: =VLOOKUP("cup",Data!F2:H4,2,FALSE) -> #N/A
A4: =VLOOKUP(4,Data!A1:A10,1) -> 4
A5: =VLOOKUP(4.5,Data!A1:A10,1,TRUE) -> 4
A6: =VLOOKUP(0,Data!A1:A10,1) -> #N/A
A7: =VLOOKUP("b*",Data!F2:H4,3,FALSE) -> 12
A8: =VLOOKUP("book",Data!F2:H4,4,FALSE) -> #REF!
A9: =HLOOKUP("Qty",Data!F1:H4,3,FALSE) -> 1
A10: =INDEX(Data!F2:H4,2,3) -> 12
A11: =INDEX(Data!A1:A10,4) -> 4
A12: =INDEX(Data!F2:H4,4,1) -> #REF!
A13: =MATCH("ink",Data!F2:F4,0) -> 3
A14: =MATCH(5.5,Data!A1:A10,1) -> 5
A15: =MATCH(5.5,Data!A1:A10) -> 5
A16: =MATCH("zzz",Data!F2:F4,0) -> #N/A
A17: =MATCH("i*",Data!F2:F4,0) -> 3
A18: =_xlfn.XLOOKUP("ink",Data!F2:F4,Data!H2:H4) -> 4.25
A19: =_xlfn.XLOOKUP("cup",Data!F2:F4,Data!H2:H4,"none") -> none
A20: =_xlfn.XLOOKUP("cup",Data!F2:F4,Data!H2:H4) -> #N/A
A21: =_xlfn.XLOOKUP(4.5,Data!A1:A10,Data!A1:A10,,-1) -> 4
A22: =_xlfn.XLOOKUP(4.5,Data!A1:A10,Data!A1:A10,,1) -> 5
A23: =LOOKUP(4.5,Data!A1:A10) -> 4
A24: =CHOOSE(MATCH("y",Data!C1:C5,0),"a","b","c") -> b
A25: =INDEX(Data!D1:D5,MATCH("z",Data!C1:C5,0)) -> 30
A26: =SUMPRODUCT((Data!C1:C5="x")*Data!D1:D5) -> 50

Sheet Dates
A1: =DATE(2020,1,15) -> 43845
A2: =DATE(2020,13,1) -> 44197
A3: =DATE(2020,1,0) -> 43830
A4: =DATE(1900,2,29) -> 60
A5: =DATE(99,1,1) -> 36161
A6: =YEAR(Data!B10) -> 2020
A7: =MONTH(Data!B10) -> 1
A8: =DAY(Data!B10) -> 15
A9: =WEEKDAY(Data!B10) -> 4
A10: =WEEKDAY(Data!B10,2) -> 3
A11: =EDATE(Data!B10,1) -> 43876
A12: =EDATE(DATE(2020,1,31),1) -> 43890
A13: =EOMONTH(Data!B10,0) -> 43861
A14: =EOMONTH(Data!B10,-1) -> 43830
A15: =DATEDIF(DATE(2020,1,15),DATE(2021,3,1),"m") -> 13
A16: =DATEDIF(DATE(2020,1,15),DATE(2021,3,1),"d") -> 411
A17: =DATEDIF(DATE(2020,1,15),DATE(2021,3,1),"y") -> 1
A18: =DATEDIF(DATE(2020,1,15),DATE(2021,3,1),"md") -> 14
A19: =DATEVALUE("2020-01-15") -> 43845
A20: =DATEVALUE("1/15/2020") -> 43845
A21: =TIME(12,30,0) -> 0.52083333
A22: =TIME(25,0,0) -> 0.041666667
A23: =HOUR(0.75) -> 18
A24: =MINUTE(0.7534) -> 4
A25: =SECOND(0.75342) -> 55
A26: =TIMEVALUE("6:45 PM") -> 0.78125
A27: =_xlfn.DAYS(DATE(2021,1,1),DATE(2020,1,1)) -> 366
A28: =NETWORKDAYS(DATE(2020,1,1),DATE(2020,1,31)) -> 23
A29: =WORKDAY(DATE(2020,1,1),10) -> 43845
A30: =YEARFRAC(DATE(2020,1,1),DATE(2020,7,1)) -> 0.5
A31: =WEEKNUM(Data!B10) -> 3
A32: =_xlfn.ISOWEEKNUM(DATE(2021,1,1)) -> 53
A33: =DAY(0) -> 0
A34: =YEAR(0) -> 1900
A35: =MONTH(-1) -> #NUM!

Sheet NearZero
A1: =0.1+0.2-0.3 -> 0
A2: =(0.1+0.2-0.3) -> 5.5511151e-17
A3: =(0.1+0.2)-0.3 -> 0
A4: =0.1+(0.2-0.3) -> 0
A5: =-(0.1+0.2)+0.3 -> 0
A6: =0.3-(0.1+0.2) -> 0
A7: =1*(0.1+0.2-0.3) -> 5.5511151e-17
A8: =(0.1+0.2-0.3)*1 -> 5.5511151e-17
A9: =(0.1+0.2-0.3)/1 -> 5.5511151e-17
A10: =+(0.1+0.2-0.3) -> 5.5511151e-17
A11: =-(0.1+0.2-0.3) -> -5.5511151e-17
A12: =--(0.1+0.2-0.3) -> 5.5511151e-17
A13: =(0.1+0.2-0.3)% -> 5.5511151e-19
A14: =SUM(0.1+0.2-0.3) -> 5.5511151e-17
A15: =SUM(0.1,0.2,-0.3) -> 0
A16: =SUM(0.3,-0.1,-0.2) -> 0
A17: =ABS(0.1+0.2-0.3) -> 5.5511151e-17
A18: =IF(TRUE,0.1+0.2-0.3) -> 5.5511151e-17
A19: =(0.1+0.2-0.3)&"" -> 5.55111512312578E-17
A20: =0.1+0.2-0.3=0 -> FALSE
A21: =0.1+0.2=0.3 -> TRUE
A22: =0.3=0.1+0.2 -> TRUE
A23: =0.1+0.2-0.3>0 -> TRUE
A24: =0.1+0.2>0.3 -> FALSE
A25: =0.1+0.2<>0.3 -> FALSE
A26: =MAX(0.1+0.2-0.3) -> 5.5511151e-17
A27: =N(0.1+0.2-0.3) -> 5.5511151e-17
A28: =0.1+0.2-0.3+0 -> 5.5511151e-17
A29: =0+0.1+0.2-0.3 -> 0
A30: =0.1-0.3+0.2 -> 0
A31: =(0.1+0.2)-(0.3) -> 0
A32: =0.3-0.2-0.1 -> 0
A33: =1*(1-0.9-0.1) -> -2.7755576e-17
A34: =1-0.9-0.1 -> 0
A35: =(1-0.9-0.1) -> -2.7755576e-17
A36: =0.3-0.1-0.2 -> 0
A37: =0.7-0.6-0.1 -> 0
A38: =1.1-1-0.1 -> 0
A39: =4.35-4.34-0.01 -> -2.1337099e-16
A40: =100.1-100-0.1 -> -5.689893e-15
...

Sheet Power
A1: =2^0.5 -> 1.4142136
A2: =10^0.3 -> 1.9952623
A3: =1.1^100 -> 13780.612
A4: =3^-3 -> 0.037037037
A5: =(-8)^(1/3) -> -2
A6: =(-8)^(2/3) -> #NUM!
A7: =(-27)^(1/3) -> -3
A8: =(-2)^(1/5) -> -1.1486984
A9: =(-32)^0.2 -> -2
A10: =(-2)^0.5 -> #NUM!
A11: =8^(1/3) -> 2
A12: =1000^(1/3) -> 10
A13: =7^(1/7) -> 1.3204692
A14: =1.0000001^10000000 -> 2.7182817
A15: =0.5^1074 -> 0
A16: =2^-1022 -> 2.2250739e-308
A17: =2^-1023 -> 0
A18: =2^-1074 -> 0
A19: =2^-1075 -> 0
A20: =(-8)^(1/3)*1 -> -2
A21: =(-1)^(1/3) -> -1
A22: =(-64)^(1/6) -> #NUM!
A23: =(-64)^(1/3) -> -4
A24: =(-0.001)^(1/3) -> -0.1
A25: =POWER(-8,1/3) -> -2
A26: =POWER(10,-2) -> 0.01
A27: =POWER(0,0) -> #NUM!
A28: =POWER(0,-1) -> #DIV/0!
A29: =POWER(-1,0.5) -> #NUM!
A30: =10^15 -> 1e+15
A31: =10^16 -> 1e+16
A32: =10^-15 -> 1e-15
A33: =2^53 -> 9.0071993e+15
A34: =3^40 -> 1.2157665e+19
A35: =1.5^2.5 -> 2.755676
A36: =(-1.5)^3 -> -3.375
A37: =(-2)^-3 -> -0.125
A38: =(-8)^-(1/3) -> -0.5
A39: =(-8)^0.333333333333333 -> -2
A40: =(-8)^(1/3+0) -> -2
...

Sheet Errors
A1: =SUM(#N/A,#DIV/0!) -> #N/A
A2: =SUM(#DIV/0!,#N/A) -> #DIV/0!
A3: =#N/A&#DIV/0! -> #N/A
A4: =MAX(1/0,NA()) -> #DIV/0!
A5: =IF(#N/A,1,2) -> #N/A
A6: =AND(#N/A,FALSE) -> #N/A
A7: =AND(FALSE,#N/A) -> #N/A
A8: =1/0=NA() -> #DIV/0!
A9: =NA()=1/0 -> #N/A
A10: =-#N/A -> #N/A
A11: =#N/A% -> #N/A
A12: =#REF! -> #REF!
A13: =#NULL! -> #NULL!
A14: =#NAME? -> #NAME?
A15: =#NUM! -> #NUM!
A16: =#VALUE! -> #VALUE!
A17: =#GETTING_DATA -> #N/A
A18: =ABS(#N/A) -> #N/A
A19: =LEN(#DIV/0!) -> #DIV/0!
A20: ="a"+#N/A -> #VALUE!
A21: =#N/A+"a" -> #N/A
A22: ="a"*1/0 -> #VALUE!
A23: =1/0*"a" -> #DIV/0!
A24: =Data!B1*Data!B5 -> #VALUE!
A25: =Data!B5*Data!B1 -> #N/A
A26: =NOSUCHFUNCTION(1) -> #NAME?
A27: =nosuchname -> #NAME?
A28: =nosuchname+1 -> #NAME?
A29: =SUM(nosuchname) -> #NAME?

Sheet Literals
A1: =1.23456789012345 -> 1.2345679
A2: =2.99999999999999 -> 3
A3: =0.3 -> 0.3
A4: =1234567890123450000 -> 1.2345679e+18
A5: =0.123456789012345 -> 0.12345679
A6: =123456789012345 -> 123456789012345
A7: =9.99999999999999 -> 10
A8: =1 -> 1
A9: =1 -> 1
A10: =0.1+0.2 -> 0.3
A11: =1234567890123450 -> 1.2345679e+15
A12: =1234567890123450 -> 1.2345679e+15
A13: =9999999999999990 -> 1e+16
A14: =99999999999999900 -> 1e+17
A17: =1E-307 -> 1e-307
A18: =0 -> 0
A19: =0 -> 0
A20: =0 -> 0
A22: =0.5 -> 0.5
A23: =5 -> 5
A24: =100000 -> 100000
A25: =100000 -> 100000
A26: =100000 -> 100000
A27: =1E-21 -> 1e-21

Sheet ToText
A1: =Numbers!A1&"" -> 0
A2: =Numbers!A2&"" -> 1
A3: =Numbers!A3&"" -> -1
A4: =Numbers!A4&"" -> 0.5
A5: =Numbers!A5&"" -> 1.5
A6: =Numbers!A6&"" -> 2.5
A7: =Numbers!A7&"" -> -2.5
A8: =Numbers!A8&"" -> 0.1
A9: =Numbers!A9&"" -> 0.2
A10: =Numbers!A10&"" -> 0.3
A11: =Numbers!A11&"" -> 0.3
A12: =Numbers!A12&"" -> 0.333333333333333
... A190: =Numbers!A190&"" -> -123.456

Sheet General
A1: =TEXT(Numbers!A1,"General") -> 0
A2: =TEXT(Numbers!A2,"General") -> 1
A3: =TEXT(Numbers!A3,"General") -> -1
A4: =TEXT(Numbers!A4,"General") -> 0.5
A5: =TEXT(Numbers!A5,"General") -> 1.5
A6: =TEXT(Numbers!A6,"General") -> 2.5
A7: =TEXT(Numbers!A7,"General") -> -2.5
A8: =TEXT(Numbers!A8,"General") -> 0.1
A9: =TEXT(Numbers!A9,"General") -> 0.2
A10: =TEXT(Numbers!A10,"General") -> 0.3
A11: =TEXT(Numbers!A11,"General") -> 0.3
A12: =TEXT(Numbers!A12,"General") -> 0.333333333
... A190: =TEXT(Numbers!A190,"General") -> -123.456

Sheet Difference
A1: =Pairs!B1-Pairs!A1 -> 0
A2: =Pairs!B2-Pairs!A2 -> 0
A3: =Pairs!B3-Pairs!A3 -> 0
A4: =Pairs!B4-Pairs!A4 -> 0
A5: =Pairs!B5-Pairs!A5 -> 0
A6: =Pairs!B6-Pairs!A6 -> 0
A7: =Pairs!B7-Pairs!A7 -> 0
A8: =Pairs!B8-Pairs!A8 -> 0
A9: =Pairs!B9-Pairs!A9 -> 0
A10: =Pairs!B10-Pairs!A10 -> 0
A11: =Pairs!B11-Pairs!A11 -> 0
A12: =Pairs!B12-Pairs!A12 -> 0
... A322: =Pairs!B322-Pairs!A322 -> -6.0908213e+287

Sheet DifferenceSum
A1: =SUM(Pairs!B1,-Pairs!A1) -> 0
A2: =SUM(Pairs!B2,-Pairs!A2) -> 0
A3: =SUM(Pairs!B3,-Pairs!A3) -> 0
A4: =SUM(Pairs!B4,-Pairs!A4) -> 0
A5: =SUM(Pairs!B5,-Pairs!A5) -> 0
A6: =SUM(Pairs!B6,-Pairs!A6) -> 0
A7: =SUM(Pairs!B7,-Pairs!A7) -> 0
A8: =SUM(Pairs!B8,-Pairs!A8) -> 0
A9: =SUM(Pairs!B9,-Pairs!A9) -> 0
A10: =SUM(Pairs!B10,-Pairs!A10) -> 0
A11: =SUM(Pairs!B11,-Pairs!A11) -> 0
A12: =SUM(Pairs!B12,-Pairs!A12) -> 0
... A322: =SUM(Pairs!B322,-Pairs!A322) -> -6.0908213e+287

Sheet Equal
A1: =Pairs!A1=Pairs!B1 -> TRUE
A2: =Pairs!A2=Pairs!B2 -> TRUE
A3: =Pairs!A3=Pairs!B3 -> TRUE
A4: =Pairs!A4=Pairs!B4 -> TRUE
A5: =Pairs!A5=Pairs!B5 -> TRUE
A6: =Pairs!A6=Pairs!B6 -> TRUE
A7: =Pairs!A7=Pairs!B7 -> TRUE
A8: =Pairs!A8=Pairs!B8 -> TRUE
A9: =Pairs!A9=Pairs!B9 -> TRUE
A10: =Pairs!A10=Pairs!B10 -> FALSE
A11: =Pairs!A11=Pairs!B11 -> TRUE
A12: =Pairs!A12=Pairs!B12 -> FALSE
... A322: =Pairs!A322=Pairs!B322 -> FALSE

Sheet Less
A1: =Pairs!A1<Pairs!B1 -> FALSE
A2: =Pairs!A2<Pairs!B2 -> FALSE
A3: =Pairs!A3<Pairs!B3 -> FALSE
A4: =Pairs!A4<Pairs!B4 -> FALSE
A5: =Pairs!A5<Pairs!B5 -> FALSE
A6: =Pairs!A6<Pairs!B6 -> FALSE
A7: =Pairs!A7<Pairs!B7 -> FALSE
A8: =Pairs!A8<Pairs!B8 -> FALSE
A9: =Pairs!A9<Pairs!B9 -> FALSE
A10: =Pairs!A10<Pairs!B10 -> FALSE
A11: =Pairs!A11<Pairs!B11 -> FALSE
A12: =Pairs!A12<Pairs!B12 -> FALSE
... A322: =Pairs!A322<Pairs!B322 -> FALSE

Sheet Coerce
A1: ="1"+0 -> 1
A2: ="-1"+0 -> -1
A3: ="+1"+0 -> 1
A4: ="1.5"+0 -> 1.5
A5: =".5"+0 -> 0.5
A6: ="5."+0 -> 5
A7: ="1e3"+0 -> 1000
A8: ="1E3"+0 -> 1000
A9: ="1e+3"+0 -> 1000
A10: ="1e-3"+0 -> 0.001
A11: ="1E"+0 -> #VALUE!
A12: ="e3"+0 -> #VALUE!
A13: ="1.5.2"+0 -> #VALUE!
A14: ="1,000"+0 -> 1000
A15: ="1,000.5"+0 -> 1000.5
A16: ="1,00"+0 -> #VALUE!
A17: ="10,00,000"+0 -> #VALUE!
A18: =",100"+0 -> #VALUE!
A19: ="100,"+0 -> #VALUE!
A20: ="1 000"+0 -> #VALUE!
A21: =" 1"+0 -> 1
A22: ="1 "+0 -> 1
A23: ="01"+0 -> 1
A24: ="00.5"+0 -> 0.5
A25: ="1_000"+0 -> #VALUE!
A26: ="0x1F"+0 -> #VALUE!
A27: ="&H1F"+0 -> #VALUE!
A28: ="1d2"+0 -> #VALUE!
A29: ="Infinity"+0 -> #VALUE!
A30: ="NaN"+0 -> #VALUE!
A31: ="1e308"+0 -> #VALUE!
A32: ="1e309"+0 -> #VALUE!
A33: ="-0"+0 -> 0
A34: ="1e-400"+0 -> #VALUE!
A35: ="50%"+0 -> 0.5
A36: ="%50"+0 -> 0.5
A37: ="50 %"+0 -> 0.5
A38: ="5%%"+0 -> #VALUE!
A39: ="-50%"+0 -> -0.5
A40: ="1.5%"+0 -> 0.015
...

Sheet Value
A1: =VALUE("1") -> 1
A2: =VALUE("-1") -> -1
A3: =VALUE("+1") -> 1
A4: =VALUE("1.5") -> 1.5
A5: =VALUE(".5") -> 0.5
A6: =VALUE("5.") -> 5
A7: =VALUE("1e3") -> 1000
A8: =VALUE("1E3") -> 1000
A9: =VALUE("1e+3") -> 1000
A10: =VALUE("1e-3") -> 0.001
A11: =VALUE("1E") -> #VALUE!
A12: =VALUE("e3") -> #VALUE!
A13: =VALUE("1.5.2") -> #VALUE!
A14: =VALUE("1,000") -> 1000
A15: =VALUE("1,000.5") -> 1000.5
A16: =VALUE("1,00") -> #VALUE!
A17: =VALUE("10,00,000") -> #VALUE!
A18: =VALUE(",100") -> #VALUE!
A19: =VALUE("100,") -> #VALUE!
A20: =VALUE("1 000") -> #VALUE!
A21: =VALUE(" 1") -> 1
A22: =VALUE("1 ") -> 1
A23: =VALUE("01") -> 1
A24: =VALUE("00.5") -> 0.5
A25: =VALUE("1_000") -> #VALUE!
A26: =VALUE("0x1F") -> #VALUE!
A27: =VALUE("&H1F") -> #VALUE!
A28: =VALUE("1d2") -> #VALUE!
A29: =VALUE("Infinity") -> #VALUE!
A30: =VALUE("NaN") -> #VALUE!
A31: =VALUE("1e308") -> #VALUE!
A32: =VALUE("1e309") -> #VALUE!
A33: =VALUE("-0") -> 0
A34: =VALUE("1e-400") -> #VALUE!
A35: =VALUE("50%") -> 0.5
A36: =VALUE("%50") -> 0.5
A37: =VALUE("50 %") -> 0.5
A38: =VALUE("5%%") -> #VALUE!
A39: =VALUE("-50%") -> -0.5
A40: =VALUE("1.5%") -> 0.015
...

Sheet DateValue
A1: =DATEVALUE("1") -> #VALUE!
A2: =DATEVALUE("-1") -> #VALUE!
A3: =DATEVALUE("+1") -> #VALUE!
A4: =DATEVALUE("1.5") -> #VALUE!
A5: =DATEVALUE(".5") -> #VALUE!
A6: =DATEVALUE("5.") -> #VALUE!
A7: =DATEVALUE("1e3") -> #VALUE!
A8: =DATEVALUE("1E3") -> #VALUE!
A9: =DATEVALUE("1e+3") -> #VALUE!
A10: =DATEVALUE("1e-3") -> #VALUE!
A11: =DATEVALUE("1E") -> #VALUE!
A12: =DATEVALUE("e3") -> #VALUE!
A13: =DATEVALUE("1.5.2") -> #VALUE!
A14: =DATEVALUE("1,000") -> #VALUE!
A15: =DATEVALUE("1,000.5") -> #VALUE!
A16: =DATEVALUE("1,00") -> #VALUE!
A17: =DATEVALUE("10,00,000") -> #VALUE!
A18: =DATEVALUE(",100") -> #VALUE!
A19: =DATEVALUE("100,") -> #VALUE!
A20: =DATEVALUE("1 000") -> #VALUE!
A21: =DATEVALUE(" 1") -> #VALUE!
A22: =DATEVALUE("1 ") -> #VALUE!
A23: =DATEVALUE("01") -> #VALUE!
A24: =DATEVALUE("00.5") -> #VALUE!
A25: =DATEVALUE("1_000") -> #VALUE!
A26: =DATEVALUE("0x1F") -> #VALUE!
A27: =DATEVALUE("&H1F") -> #VALUE!
A28: =DATEVALUE("1d2") -> #VALUE!
A29: =DATEVALUE("Infinity") -> #VALUE!
A30: =DATEVALUE("NaN") -> #VALUE!
A31: =DATEVALUE("1e308") -> #VALUE!
A32: =DATEVALUE("1e309") -> #VALUE!
A33: =DATEVALUE("-0") -> #VALUE!
A34: =DATEVALUE("1e-400") -> #VALUE!
A35: =DATEVALUE("50%") -> #VALUE!
A36: =DATEVALUE("%50") -> #VALUE!
A37: =DATEVALUE("50 %") -> #VALUE!
A38: =DATEVALUE("5%%") -> #VALUE!
A39: =DATEVALUE("-50%") -> #VALUE!
A40: =DATEVALUE("1.5%") -> #VALUE!
...

Sheet TimeValue
A1: =TIMEVALUE("1") -> #VALUE!
A2: =TIMEVALUE("-1") -> #VALUE!
A3: =TIMEVALUE("+1") -> #VALUE!
A4: =TIMEVALUE("1.5") -> #VALUE!
A5: =TIMEVALUE(".5") -> #VALUE!
A6: =TIMEVALUE("5.") -> #VALUE!
A7: =TIMEVALUE("1e3") -> #VALUE!
A8: =TIMEVALUE("1E3") -> #VALUE!
A9: =TIMEVALUE("1e+3") -> #VALUE!
A10: =TIMEVALUE("1e-3") -> #VALUE!
A11: =TIMEVALUE("1E") -> #VALUE!
A12: =TIMEVALUE("e3") -> #VALUE!
A13: =TIMEVALUE("1.5.2") -> #VALUE!
A14: =TIMEVALUE("1,000") -> #VALUE!
A15: =TIMEVALUE("1,000.5") -> #VALUE!
A16: =TIMEVALUE("1,00") -> #VALUE!
A17: =TIMEVALUE("10,00,000") -> #VALUE!
A18: =TIMEVALUE(",100") -> #VALUE!
A19: =TIMEVALUE("100,") -> #VALUE!
A20: =TIMEVALUE("1 000") -> #VALUE!
A21: =TIMEVALUE(" 1") -> #VALUE!
A22: =TIMEVALUE("1 ") -> #VALUE!
A23: =TIMEVALUE("01") -> #VALUE!
A24: =TIMEVALUE("00.5") -> #VALUE!
A25: =TIMEVALUE("1_000") -> #VALUE!
A26: =TIMEVALUE("0x1F") -> #VALUE!
A27: =TIMEVALUE("&H1F") -> #VALUE!
A28: =TIMEVALUE("1d2") -> #VALUE!
A29: =TIMEVALUE("Infinity") -> #VALUE!
A30: =TIMEVALUE("NaN") -> #VALUE!
A31: =TIMEVALUE("1e308") -> #VALUE!
A32: =TIMEVALUE("1e309") -> #VALUE!
A33: =TIMEVALUE("-0") -> #VALUE!
A34: =TIMEVALUE("1e-400") -> #VALUE!
A35: =TIMEVALUE("50%") -> #VALUE!
A36: =TIMEVALUE("%50") -> #VALUE!
A37: =TIMEVALUE("50 %") -> #VALUE!
A38: =TIMEVALUE("5%%") -> #VALUE!
A39: =TIMEVALUE("-50%") -> #VALUE!
A40: =TIMEVALUE("1.5%") -> #VALUE!
...

Sheet WordsEqual
A1: ="a"="a" -> TRUE
A2: ="a"="A" -> TRUE
A3: ="a"="b" -> FALSE
A4: ="a"="B" -> FALSE
A5: ="a"="" -> FALSE
A6: ="a"=" " -> FALSE
A7: ="a"="ab" -> FALSE
A8: ="a"="a b" -> FALSE
A9: ="a"="a-b" -> FALSE
A10: ="a"="a'b" -> FALSE
A11: ="a"="co-op" -> FALSE
A12: ="a"="coop" -> FALSE
A13: ="a"="cop" -> FALSE
A14: ="a"="ß" -> FALSE
A15: ="a"="ss" -> FALSE
A16: ="a"="æ" -> FALSE
A17: ="a"="ae" -> FALSE
A18: ="a"="é" -> FALSE
A19: ="a"="e" -> FALSE
A20: ="a"="f" -> FALSE
A21: ="a"="É" -> FALSE
A22: ="a"="1" -> FALSE
A23: ="a"="10" -> FALSE
A24: ="a"="9" -> FALSE
A25: ="a"="a1" -> FALSE
A26: ="a"="a10" -> FALSE
A27: ="a"="a2" -> FALSE
A28: ="a"="_" -> FALSE
A29: ="a"="-" -> FALSE
A30: ="a"="~" -> FALSE
A31: ="a"="z" -> FALSE
A32: ="a"="Ω" -> FALSE
A33: ="a"="ω" -> FALSE
A34: ="A"="a" -> TRUE
A35: ="A"="A" -> TRUE
A36: ="A"="b" -> FALSE
A37: ="A"="B" -> FALSE
A38: ="A"="" -> FALSE
A39: ="A"=" " -> FALSE
A40: ="A"="ab" -> FALSE
...

Sheet WordsLess
A1: ="a"<"a" -> FALSE
A2: ="a"<"A" -> FALSE
A3: ="a"<"b" -> TRUE
A4: ="a"<"B" -> TRUE
A5: ="a"<"" -> FALSE
A6: ="a"<" " -> FALSE
A7: ="a"<"ab" -> TRUE
A8: ="a"<"a b" -> TRUE
A9: ="a"<"a-b" -> TRUE
A10: ="a"<"a'b" -> TRUE
A11: ="a"<"co-op" -> TRUE
A12: ="a"<"coop" -> TRUE
A13: ="a"<"cop" -> TRUE
A14: ="a"<"ß" -> TRUE
A15: ="a"<"ss" -> TRUE
A16: ="a"<"æ" -> TRUE
A17: ="a"<"ae" -> TRUE
A18: ="a"<"é" -> TRUE
A19: ="a"<"e" -> TRUE
A20: ="a"<"f" -> TRUE
A21: ="a"<"É" -> TRUE
A22: ="a"<"1" -> FALSE
A23: ="a"<"10" -> FALSE
A24: ="a"<"9" -> FALSE
A25: ="a"<"a1" -> TRUE
A26: ="a"<"a10" -> TRUE
A27: ="a"<"a2" -> TRUE
A28: ="a"<"_" -> FALSE
A29: ="a"<"-" -> FALSE
A30: ="a"<"~" -> FALSE
A31: ="a"<"z" -> TRUE
A32: ="a"<"Ω" -> TRUE
A33: ="a"<"ω" -> TRUE
A34: ="A"<"a" -> FALSE
A35: ="A"<"A" -> FALSE
A36: ="A"<"b" -> TRUE
A37: ="A"<"B" -> TRUE
A38: ="A"<"" -> FALSE
A39: ="A"<" " -> FALSE
A40: ="A"<"ab" -> TRUE
...

Sheet PowerData
A1: =Powers!A1^Powers!B1 -> 501.65893
A2: =Powers!A2^Powers!B2 -> 147547.59
A3: =Powers!A3^Powers!B3 -> 2.3244763
A4: =Powers!A4^Powers!B4 -> 1.9073915
A5: =Powers!A5^Powers!B5 -> 32.477979
A6: =Powers!A6^Powers!B6 -> 266.54086
A7: =Powers!A7^Powers!B7 -> 792.2137
A8: =Powers!A8^Powers!B8 -> 0.00012923554
A9: =Powers!A9^Powers!B9 -> 2.1659895
A10: =Powers!A10^Powers!B10 -> 24.899718
A11: =Powers!A11^Powers!B11 -> 0.00036037975
A12: =Powers!A12^Powers!B12 -> 13322397
... A654: =Powers!A654^Powers!B654 -> 1448.1547

Sheet PowerFunction
A1: =POWER(Powers!A1,Powers!B1) -> 501.65893
A2: =POWER(Powers!A2,Powers!B2) -> 147547.59
A3: =POWER(Powers!A3,Powers!B3) -> 2.3244763
A4: =POWER(Powers!A4,Powers!B4) -> 1.9073915
A5: =POWER(Powers!A5,Powers!B5) -> 32.477979
A6: =POWER(Powers!A6,Powers!B6) -> 266.54086
A7: =POWER(Powers!A7,Powers!B7) -> 792.2137
A8: =POWER(Powers!A8,Powers!B8) -> 0.00012923554
A9: =POWER(Powers!A9,Powers!B9) -> 2.1659895
A10: =POWER(Powers!A10,Powers!B10) -> 24.899718
A11: =POWER(Powers!A11,Powers!B11) -> 0.00036037975
A12: =POWER(Powers!A12,Powers!B12) -> 13322397
... A60: =POWER(Powers!A60,Powers!B60) -> 551736.38

Sheet DifferenceReversed
A1: =Pairs!A1-Pairs!B1 -> 0
A2: =Pairs!A2-Pairs!B2 -> 0
A3: =Pairs!A3-Pairs!B3 -> 0
A4: =Pairs!A4-Pairs!B4 -> 0
A5: =Pairs!A5-Pairs!B5 -> 0
A6: =Pairs!A6-Pairs!B6 -> 0
A7: =Pairs!A7-Pairs!B7 -> 0
A8: =Pairs!A8-Pairs!B8 -> 0
A9: =Pairs!A9-Pairs!B9 -> 0
A10: =Pairs!A10-Pairs!B10 -> 0
A11: =Pairs!A11-Pairs!B11 -> 0
A12: =Pairs!A12-Pairs!B12 -> 0
... A322: =Pairs!A322-Pairs!B322 -> 6.0908213e+287

Sheet SumNested
A1: =1*SUM(Pairs!B1,-Pairs!A1) -> 0
A2: =1*SUM(Pairs!B2,-Pairs!A2) -> 0
A3: =1*SUM(Pairs!B3,-Pairs!A3) -> 0
A4: =1*SUM(Pairs!B4,-Pairs!A4) -> 0
A5: =1*SUM(Pairs!B5,-Pairs!A5) -> 0
A6: =1*SUM(Pairs!B6,-Pairs!A6) -> 0
A7: =1*SUM(Pairs!B7,-Pairs!A7) -> 0
A8: =1*SUM(Pairs!B8,-Pairs!A8) -> 0
A9: =1*SUM(Pairs!B9,-Pairs!A9) -> 0
A10: =1*SUM(Pairs!B10,-Pairs!A10) -> 0
A11: =1*SUM(Pairs!B11,-Pairs!A11) -> 0
A12: =1*SUM(Pairs!B12,-Pairs!A12) -> 0
... A322: =1*SUM(Pairs!B322,-Pairs!A322) -> -6.0908213e+287

Sheet TiesText
A1: =Ties!A1&"" -> 1234567890123440
A2: =Ties!A2&"" -> 1234567890123450
A3: =Ties!A3&"" -> 1234567890123460
A4: =Ties!A4&"" -> 1234567890123470
A5: =Ties!A5&"" -> 1000000000000000
A6: =Ties!A6&"" -> 10000000000000000
A7: =Ties!A7&"" -> 9007199254740990
A8: =Ties!A8&"" -> 1125899906842620

Sheet Exp
A1: =EXP(Reals!A1) -> 0.0021276778
A2: =EXP(Reals!A2) -> 0.014077873
A3: =EXP(Reals!A3) -> 0.00048232406
A4: =EXP(Reals!A4) -> 0.020771746
A5: =EXP(Reals!A5) -> 0.022079052
A6: =EXP(Reals!A6) -> 0.0018159545
A7: =EXP(Reals!A7) -> 3.9738204
A8: =EXP(Reals!A8) -> 111.4968
A9: =EXP(Reals!A9) -> 0.0027632867
A10: =EXP(Reals!A10) -> 1.2212785
A11: =EXP(Reals!A11) -> 0.0010058737
A12: =EXP(Reals!A12) -> 13461.239
... A72: =EXP(Reals!A72) -> #NUM!

Sheet Ln
A1: =LN(ABS(Reals!A1)) -> 1.8168949
A2: =LN(ABS(Reals!A2)) -> 1.4500086
A3: =LN(ABS(Reals!A3)) -> 2.032991
A4: =LN(ABS(Reals!A4)) -> 1.3543293
A5: =LN(ABS(Reals!A5)) -> 1.3384493
A6: =LN(ABS(Reals!A6)) -> 1.842317
A7: =LN(ABS(Reals!A7)) -> 0.32188635
A8: =LN(ABS(Reals!A8)) -> 1.5505359
A9: =LN(ABS(Reals!A9)) -> 1.7734825
A10: =LN(ABS(Reals!A10)) -> -1.6099467
A11: =LN(ABS(Reals!A11)) -> 1.9317966
A12: =LN(ABS(Reals!A12)) -> 2.2520883
... A72: =LN(ABS(Reals!A72)) -> 16.118096

Sheet Sin
A1: =SIN(Reals!A1) -> 0.13009141
A2: =SIN(Reals!A2) -> 0.90077828
A3: =SIN(Reals!A3) -> -0.97652895
A4: =SIN(Reals!A4) -> 0.66878175
A5: =SIN(Reals!A5) -> 0.62218714
A6: =SIN(Reals!A6) -> -0.027955109
A7: =SIN(Reals!A7) -> 0.9818019
A8: =SIN(Reals!A8) -> -0.99999871
A9: =SIN(Reals!A9) -> 0.3818996
A10: =SIN(Reals!A10) -> 0.19856963
A11: =SIN(Reals!A11) -> -0.57998762
A12: =SIN(Reals!A12) -> -0.082697131
... A72: =SIN(Reals!A72) -> 0.42054779

Sheet Cos
A1: =COS(Reals!A1) -> 0.991502
A2: =COS(Reals!A2) -> -0.43427927
A3: =COS(Reals!A3) -> 0.21538619
A4: =COS(Reals!A4) -> -0.74345879
A5: =COS(Reals!A5) -> -0.78286855
A6: =COS(Reals!A6) -> 0.99960918
A7: =COS(Reals!A7) -> 0.18990793
A8: =COS(Reals!A8) -> 0.0016069278
A9: =COS(Reals!A9) -> 0.92420382
A10: =COS(Reals!A10) -> 0.98008678
A11: =COS(Reals!A11) -> 0.81462529
A12: =COS(Reals!A12) -> -0.99657473
... A72: =COS(Reals!A72) -> -0.90727039

Sheet Tan
A1: =TAN(Reals!A1) -> 0.1312064
A2: =TAN(Reals!A2) -> -2.0741913
A3: =TAN(Reals!A3) -> -4.5338513
A4: =TAN(Reals!A4) -> -0.89955456
A5: =TAN(Reals!A5) -> -0.79475301
A6: =TAN(Reals!A6) -> -0.027966039
A7: =TAN(Reals!A7) -> 5.1698838
A8: =TAN(Reals!A8) -> -622.30469
A9: =TAN(Reals!A9) -> 0.41322011
A10: =TAN(Reals!A10) -> 0.20260413
A11: =TAN(Reals!A11) -> -0.7119686
A12: =TAN(Reals!A12) -> 0.082981365
... A72: =TAN(Reals!A72) -> -0.46353083

Sheet Atan
A1: =ATAN(Reals!A1) -> -1.4096756
A2: =ATAN(Reals!A2) -> -1.3403935
A3: =ATAN(Reals!A3) -> -1.4405938
A4: =ATAN(Reals!A4) -> -1.3181897
A5: =ATAN(Reals!A5) -> -1.31432
A6: =ATAN(Reals!A6) -> -1.4136529
A7: =ATAN(Reals!A7) -> 0.94363199
A8: =ATAN(Reals!A8) -> 1.3617609
A9: =ATAN(Reals!A9) -> -1.4026581
A10: =ATAN(Reals!A10) -> 0.19729774
A11: =ATAN(Reals!A11) -> -1.4269099
A12: =ATAN(Reals!A12) -> 1.4660023
... A72: =ATAN(Reals!A72) -> 1.5707962

Sheet Sinh
A1: =SINH(Reals!A1) -> -234.99692
A2: =SINH(Reals!A2) -> -35.509689
A3: =SINH(Reals!A3) -> -1036.6472
A4: =SINH(Reals!A4) -> -24.060774
A5: =SINH(Reals!A5) -> -22.634861
A6: =SINH(Reals!A6) -> -275.33639
A7: =SINH(Reals!A7) -> 1.8610867
A8: =SINH(Reals!A8) -> 55.743917
A9: =SINH(Reals!A9) -> -180.94257
A10: =SINH(Reals!A10) -> 0.20123223
A11: =SINH(Reals!A11) -> -497.07982
A12: =SINH(Reals!A12) -> 6730.6194
... A72: =SINH(Reals!A72) -> #NUM!

Sheet Cosh
A1: =COSH(Reals!A1) -> 234.99905
A2: =COSH(Reals!A2) -> 35.523767
A3: =COSH(Reals!A3) -> 1036.6477
A4: =COSH(Reals!A4) -> 24.081545
A5: =COSH(Reals!A5) -> 22.65694
A6: =COSH(Reals!A6) -> 275.3382
A7: =COSH(Reals!A7) -> 2.1127337
A8: =COSH(Reals!A8) -> 55.752885
A9: =COSH(Reals!A9) -> 180.94533
A10: =COSH(Reals!A10) -> 1.0200463
A11: =COSH(Reals!A11) -> 497.08082
A12: =COSH(Reals!A12) -> 6730.6195
... A72: =COSH(Reals!A72) -> #NUM!

Sheet Tanh
A1: =TANH(Reals!A1) -> -0.99999095
A2: =TANH(Reals!A2) -> -0.99960371
A3: =TANH(Reals!A3) -> -0.99999953
A4: =TANH(Reals!A4) -> -0.99913744
A5: =TANH(Reals!A5) -> -0.99902551
A6: =TANH(Reals!A6) -> -0.9999934
A7: =TANH(Reals!A7) -> 0.88089034
A8: =TANH(Reals!A8) -> 0.99983913
A9: =TANH(Reals!A9) -> -0.99998473
A10: =TANH(Reals!A10) -> 0.19727755
A11: =TANH(Reals!A11) -> -0.99999798
A12: =TANH(Reals!A12) -> 0.99999999
... A72: =TANH(Reals!A72) -> 1

Sheet Sqrt
A1: =SQRT(ABS(Reals!A1)) -> 2.4804685
A2: =SQRT(ABS(Reals!A2)) -> 2.0647399
A3: =SQRT(ABS(Reals!A3)) -> 2.7634931
A4: =SQRT(ABS(Reals!A4)) -> 1.968289
A5: =SQRT(ABS(Reals!A5)) -> 1.9527227
A6: =SQRT(ABS(Reals!A6)) -> 2.512199
A7: =SQRT(ABS(Reals!A7)) -> 1.1746182
A8: =SQRT(ABS(Reals!A8)) -> 2.1711739
A9: =SQRT(ABS(Reals!A9)) -> 2.4272071
A10: =SQRT(ABS(Reals!A10)) -> 0.44709984
A11: =SQRT(ABS(Reals!A11)) -> 2.6271465
A12: =SQRT(ABS(Reals!A12)) -> 3.0834347
... A72: =SQRT(ABS(Reals!A72)) -> 3162.2777

Sheet Asin
A1: =ASIN(Reals!A1/10) -> -0.66273148
A2: =ASIN(Reals!A2/10) -> -0.44041522
A3: =ASIN(Reals!A3/10) -> -0.86900884
A4: =ASIN(Reals!A4/10) -> -0.39782722
A5: =ASIN(Reals!A5/10) -> -0.39121576
A6: =ASIN(Reals!A6/10) -> -0.68298904
A7: =ASIN(Reals!A7/10) -> 0.13841434
A8: =ASIN(Reals!A8/10) -> 0.49087709
A9: =ASIN(Reals!A9/10) -> -0.629986
A10: =ASIN(Reals!A10/10) -> 0.019991159
A11: =ASIN(Reals!A11/10) -> -0.76175142
A12: =ASIN(Reals!A12/10) -> 1.2556691
... A72: =ASIN(Reals!A72/10) -> #NUM!

Sheet Acos
A1: =ACOS(Reals!A1/10) -> 2.2335278
A2: =ACOS(Reals!A2/10) -> 2.0112115
A3: =ACOS(Reals!A3/10) -> 2.4398052
A4: =ACOS(Reals!A4/10) -> 1.9686235
A5: =ACOS(Reals!A5/10) -> 1.9620121
A6: =ACOS(Reals!A6/10) -> 2.2537854
A7: =ACOS(Reals!A7/10) -> 1.432382
A8: =ACOS(Reals!A8/10) -> 1.0799192
A9: =ACOS(Reals!A9/10) -> 2.2007823
A10: =ACOS(Reals!A10/10) -> 1.5508052
A11: =ACOS(Reals!A11/10) -> 2.3325477
A12: =ACOS(Reals!A12/10) -> 0.3151272
... A72: =ACOS(Reals!A72/10) -> #NUM!

Sheet Log10
A1: =LOG10(ABS(Reals!A1)) -> 0.78906744
A2: =LOG10(ABS(Reals!A2)) -> 0.62973071
A3: =LOG10(ABS(Reals!A3)) -> 0.88291678
A4: =LOG10(ABS(Reals!A4)) -> 0.58817773
A5: =LOG10(ABS(Reals!A5)) -> 0.58128116
A6: =LOG10(ABS(Reals!A6)) -> 0.80010809
A7: =LOG10(ABS(Reals!A7)) -> 0.13979347
A8: =LOG10(ABS(Reals!A8)) -> 0.6733892
A9: =LOG10(ABS(Reals!A9)) -> 0.77021368
A10: =LOG10(ABS(Reals!A10)) -> -0.69919096
A11: =LOG10(ABS(Reals!A11)) -> 0.83896859
A12: =LOG10(ABS(Reals!A12)) -> 0.97806952
... A72: =LOG10(ABS(Reals!A72)) -> 7

Sheet Log2
A1: =LOG(ABS(Reals!A1),2) -> 2.6212253
A2: =LOG(ABS(Reals!A2),2) -> 2.0919201
A3: =LOG(ABS(Reals!A3),2) -> 2.9329861
A4: =LOG(ABS(Reals!A4),2) -> 1.9538841
A5: =LOG(ABS(Reals!A5),2) -> 1.9309742
A6: =LOG(ABS(Reals!A6),2) -> 2.6579016
A7: =LOG(ABS(Reals!A7),2) -> 0.46438384
A8: =LOG(ABS(Reals!A8),2) -> 2.2369505
A9: =LOG(ABS(Reals!A9),2) -> 2.5585945
A10: =LOG(ABS(Reals!A10),2) -> -2.3226621
A11: =LOG(ABS(Reals!A11),2) -> 2.7869933
A12: =LOG(ABS(Reals!A12),2) -> 3.2490766
... A72: =LOG(ABS(Reals!A72),2) -> 23.253497

Sheet Degrees
A1: =DEGREES(Reals!A1) -> -352.52513
A2: =DEGREES(Reals!A2) -> -244.26056
A3: =DEGREES(Reals!A3) -> -437.56181
A4: =DEGREES(Reals!A4) -> -221.97311
A5: =DEGREES(Reals!A5) -> -218.47603
A6: =DEGREES(Reals!A6) -> -361.60192
A7: =DEGREES(Reals!A7) -> 79.052589
A8: =DEGREES(Reals!A8) -> 270.09207
A9: =DEGREES(Reals!A9) -> -337.5486
A10: =DEGREES(Reals!A10) -> 11.453327
A11: =DEGREES(Reals!A11) -> -395.44967
A12: =DEGREES(Reals!A12) -> 544.74361
... A72: =DEGREES(Reals!A72) -> 5.729578e+08

Sheet Radians
A1: =RADIANS(Reals!A1) -> -0.10738529
A2: =RADIANS(Reals!A2) -> -0.074406021
A3: =RADIANS(Reals!A3) -> -0.13328895
A4: =RADIANS(Reals!A4) -> -0.067616876
A5: =RADIANS(Reals!A5) -> -0.066551604
A6: =RADIANS(Reals!A6) -> -0.11015024
A7: =RADIANS(Reals!A7) -> 0.024080796
A8: =RADIANS(Reals!A8) -> 0.08227475
A9: =RADIANS(Reals!A9) -> -0.10282318
A10: =RADIANS(Reals!A10) -> 0.003488883
A11: =RADIANS(Reals!A11) -> -0.12046086
A12: =RADIANS(Reals!A12) -> 0.16593839
... A72: =RADIANS(Reals!A72) -> 174532.93

Sheet Atan2
A1: =ATAN2(Reals!A1,Reals!A2) -> -2.5356556
A2: =ATAN2(Reals!A2,Reals!A3) -> -2.0799369
A3: =ATAN2(Reals!A3,Reals!A4) -> -2.6721257
A4: =ATAN2(Reals!A4,Reals!A5) -> -2.3641341
A5: =ATAN2(Reals!A5,Reals!A6) -> -2.1142905
A6: =ATAN2(Reals!A6,Reals!A7) -> 2.9263612
A7: =ATAN2(Reals!A7,Reals!A8) -> 1.2860616
A8: =ATAN2(Reals!A8,Reals!A9) -> -0.89595931
A9: =ATAN2(Reals!A9,Reals!A10) -> 3.1076748
A10: =ATAN2(Reals!A10,Reals!A11) -> -1.5418416
A11: =ATAN2(Reals!A11,Reals!A12) -> 2.1987186
A12: =ATAN2(Reals!A12,Reals!A13) -> -0.36147678
... A71: =ATAN2(Reals!A71,Reals!A72) -> 1.5607967
A72: =ATAN2(Reals!A72,Reals!A1) -> -6.1527241e-07

Sheet Round
A1: =ROUND(Rounding!A1,Rounding!B1) -> 2.68
A2: =ROUND(Rounding!A2,Rounding!B2) -> 2.68
A3: =ROUND(Rounding!A3,Rounding!B3) -> 2.68
A4: =ROUND(Rounding!A4,Rounding!B4) -> 2.68
A5: =ROUND(Rounding!A5,Rounding!B5) -> 2.68
A6: =ROUND(Rounding!A6,Rounding!B6) -> 1.01
A7: =ROUND(Rounding!A7,Rounding!B7) -> 1.01
A8: =ROUND(Rounding!A8,Rounding!B8) -> 1.01
A9: =ROUND(Rounding!A9,Rounding!B9) -> 1.01
A10: =ROUND(Rounding!A10,Rounding!B10) -> 1.01
A11: =ROUND(Rounding!A11,Rounding!B11) -> 0.29
A12: =ROUND(Rounding!A12,Rounding!B12) -> 0.29
... A130: =ROUND(Rounding!A130,Rounding!B130) -> 0.3

Sheet RoundUp
A1: =ROUNDUP(Rounding!A1,Rounding!B1) -> 2.68
A2: =ROUNDUP(Rounding!A2,Rounding!B2) -> 2.68
A3: =ROUNDUP(Rounding!A3,Rounding!B3) -> 2.68
A4: =ROUNDUP(Rounding!A4,Rounding!B4) -> 2.68
A5: =ROUNDUP(Rounding!A5,Rounding!B5) -> 2.68
A6: =ROUNDUP(Rounding!A6,Rounding!B6) -> 1.01
A7: =ROUNDUP(Rounding!A7,Rounding!B7) -> 1.01
A8: =ROUNDUP(Rounding!A8,Rounding!B8) -> 1.01
A9: =ROUNDUP(Rounding!A9,Rounding!B9) -> 1.01
A10: =ROUNDUP(Rounding!A10,Rounding!B10) -> 1.01
A11: =ROUNDUP(Rounding!A11,Rounding!B11) -> 0.29
A12: =ROUNDUP(Rounding!A12,Rounding!B12) -> 0.29
... A130: =ROUNDUP(Rounding!A130,Rounding!B130) -> 0.3

Sheet RoundDown
A1: =ROUNDDOWN(Rounding!A1,Rounding!B1) -> 2.67
A2: =ROUNDDOWN(Rounding!A2,Rounding!B2) -> 2.67
A3: =ROUNDDOWN(Rounding!A3,Rounding!B3) -> 2.67
A4: =ROUNDDOWN(Rounding!A4,Rounding!B4) -> 2.67
A5: =ROUNDDOWN(Rounding!A5,Rounding!B5) -> 2.67
A6: =ROUNDDOWN(Rounding!A6,Rounding!B6) -> 1
A7: =ROUNDDOWN(Rounding!A7,Rounding!B7) -> 1
A8: =ROUNDDOWN(Rounding!A8,Rounding!B8) -> 1
A9: =ROUNDDOWN(Rounding!A9,Rounding!B9) -> 1
A10: =ROUNDDOWN(Rounding!A10,Rounding!B10) -> 1
A11: =ROUNDDOWN(Rounding!A11,Rounding!B11) -> 0.28
A12: =ROUNDDOWN(Rounding!A12,Rounding!B12) -> 0.28
... A130: =ROUNDDOWN(Rounding!A130,Rounding!B130) -> 0.3

Sheet Trunc
A1: =TRUNC(Rounding!A1,Rounding!B1) -> 2.67
A2: =TRUNC(Rounding!A2,Rounding!B2) -> 2.67
A3: =TRUNC(Rounding!A3,Rounding!B3) -> 2.67
A4: =TRUNC(Rounding!A4,Rounding!B4) -> 2.67
A5: =TRUNC(Rounding!A5,Rounding!B5) -> 2.67
A6: =TRUNC(Rounding!A6,Rounding!B6) -> 1
A7: =TRUNC(Rounding!A7,Rounding!B7) -> 1
A8: =TRUNC(Rounding!A8,Rounding!B8) -> 1
A9: =TRUNC(Rounding!A9,Rounding!B9) -> 1
A10: =TRUNC(Rounding!A10,Rounding!B10) -> 1
A11: =TRUNC(Rounding!A11,Rounding!B11) -> 0.28
A12: =TRUNC(Rounding!A12,Rounding!B12) -> 0.28
... A130: =TRUNC(Rounding!A130,Rounding!B130) -> 0.3

Sheet Int
A1: =INT(Wholes!A1) -> 3
A2: =INT(Wholes!A2) -> 3
A3: =INT(Wholes!A3) -> 3
A4: =INT(Wholes!A4) -> 3
A5: =INT(Wholes!A5) -> 3
A6: =INT(Wholes!A6) -> 3
A7: =INT(Wholes!A7) -> 3
A8: =INT(Wholes!A8) -> 3
A9: =INT(Wholes!A9) -> 3
A10: =INT(Wholes!A10) -> -3
A11: =INT(Wholes!A11) -> -3
A12: =INT(Wholes!A12) -> -3
... A90: =INT(Wholes!A90) -> 3

Sheet TruncWhole
A1: =TRUNC(Wholes!A1) -> 3
A2: =TRUNC(Wholes!A2) -> 3
A3: =TRUNC(Wholes!A3) -> 3
A4: =TRUNC(Wholes!A4) -> 3
A5: =TRUNC(Wholes!A5) -> 3
A6: =TRUNC(Wholes!A6) -> 3
A7: =TRUNC(Wholes!A7) -> 3
A8: =TRUNC(Wholes!A8) -> 3
A9: =TRUNC(Wholes!A9) -> 3
A10: =TRUNC(Wholes!A10) -> -3
A11: =TRUNC(Wholes!A11) -> -3
A12: =TRUNC(Wholes!A12) -> -3
... A90: =TRUNC(Wholes!A90) -> 3

Sheet Mod
A1: =MOD(Divisions!A1,Divisions!B1) -> 0.1
A2: =MOD(Divisions!A2,Divisions!B2) -> 1.5
A3: =MOD(Divisions!A3,Divisions!B3) -> 1
A4: =MOD(Divisions!A4,Divisions!B4) -> 2
A5: =MOD(Divisions!A5,Divisions!B5) -> 3
A6: =MOD(Divisions!A6,Divisions!B6) -> 0.1
A7: =MOD(Divisions!A7,Divisions!B7) -> 0.1
A8: =MOD(Divisions!A8,Divisions!B8) -> 4.4408921e-16
A9: =MOD(Divisions!A9,Divisions!B9) -> 0.7
A10: =MOD(Divisions!A10,Divisions!B10) -> -0.7
A11: =MOD(Divisions!A11,Divisions!B11) -> #NUM!
A12: =MOD(Divisions!A12,Divisions!B12) -> #NUM!
... A28: =MOD(Divisions!A28,Divisions!B28) -> 2.2

Sheet Quotient
A1: =QUOTIENT(Divisions!A1,Divisions!B1) -> 3
A2: =QUOTIENT(Divisions!A2,Divisions!B2) -> 2
A3: =QUOTIENT(Divisions!A3,Divisions!B3) -> 3333333333
A4: =QUOTIENT(Divisions!A4,Divisions!B4) -> 44739242
A5: =QUOTIENT(Divisions!A5,Divisions!B5) -> 21428571
A6: =QUOTIENT(Divisions!A6,Divisions!B6) -> 10
A7: =QUOTIENT(Divisions!A7,Divisions!B7) -> 2
A8: =QUOTIENT(Divisions!A8,Divisions!B8) -> 10
A9: =QUOTIENT(Divisions!A9,Divisions!B9) -> -10
A10: =QUOTIENT(Divisions!A10,Divisions!B10) -> -10
A11: =QUOTIENT(Divisions!A11,Divisions!B11) -> 142857142857142
A12: =QUOTIENT(Divisions!A12,Divisions!B12) -> 833333333333333
... A28: =QUOTIENT(Divisions!A28,Divisions!B28) -> 5

Sheet Ceiling
A1: =CEILING(Divisions!A1,Divisions!B1) -> 13.2
A2: =CEILING(Divisions!A2,Divisions!B2) -> 6
A3: =CEILING(Divisions!A3,Divisions!B3) -> 10000000002
A4: =CEILING(Divisions!A4,Divisions!B4) -> 134217729
A5: =CEILING(Divisions!A5,Divisions!B5) -> 150000004
A6: =CEILING(Divisions!A6,Divisions!B6) -> 1
A7: =CEILING(Divisions!A7,Divisions!B7) -> 0.3
A8: =CEILING(Divisions!A8,Divisions!B8) -> 7
A9: =CEILING(Divisions!A9,Divisions!B9) -> -7
A10: =CEILING(Divisions!A10,Divisions!B10) -> #NUM!
A11: =CEILING(Divisions!A11,Divisions!B11) -> 1e+15
A12: =CEILING(Divisions!A12,Divisions!B12) -> 2.5e+15
... A28: =CEILING(Divisions!A28,Divisions!B28) -> 11

Sheet Floor
A1: =FLOOR(Divisions!A1,Divisions!B1) -> 9.9
A2: =FLOOR(Divisions!A2,Divisions!B2) -> 4
A3: =FLOOR(Divisions!A3,Divisions!B3) -> 9999999999
A4: =FLOOR(Divisions!A4,Divisions!B4) -> 134217726
A5: =FLOOR(Divisions!A5,Divisions!B5) -> 149999997
A6: =FLOOR(Divisions!A6,Divisions!B6) -> 1
A7: =FLOOR(Divisions!A7,Divisions!B7) -> 0.3
A8: =FLOOR(Divisions!A8,Divisions!B8) -> 7
A9: =FLOOR(Divisions!A9,Divisions!B9) -> -7
A10: =FLOOR(Divisions!A10,Divisions!B10) -> #NUM!
A11: =FLOOR(Divisions!A11,Divisions!B11) -> 1e+15
A12: =FLOOR(Divisions!A12,Divisions!B12) -> 2.5e+15
... A28: =FLOOR(Divisions!A28,Divisions!B28) -> 11

Sheet MRound
A1: =MROUND(Divisions!A1,Divisions!B1) -> 9.9
A2: =MROUND(Divisions!A2,Divisions!B2) -> 6
A3: =MROUND(Divisions!A3,Divisions!B3) -> 9999999999
A4: =MROUND(Divisions!A4,Divisions!B4) -> 134217729
A5: =MROUND(Divisions!A5,Divisions!B5) -> 149999997
A6: =MROUND(Divisions!A6,Divisions!B6) -> 1
A7: =MROUND(Divisions!A7,Divisions!B7) -> 0.3
A8: =MROUND(Divisions!A8,Divisions!B8) -> 7
A9: =MROUND(Divisions!A9,Divisions!B9) -> #NUM!
A10: =MROUND(Divisions!A10,Divisions!B10) -> #NUM!
A11: =MROUND(Divisions!A11,Divisions!B11) -> 1e+15
A12: =MROUND(Divisions!A12,Divisions!B12) -> 2.5e+15
... A28: =MROUND(Divisions!A28,Divisions!B28) -> 11

Sheet CeilingMath
A1: =_xlfn.CEILING.MATH(Divisions!A1,Divisions!B1) -> 13.2
A2: =_xlfn.CEILING.MATH(Divisions!A2,Divisions!B2) -> 6
A3: =_xlfn.CEILING.MATH(Divisions!A3,Divisions!B3) -> 10000000002
A4: =_xlfn.CEILING.MATH(Divisions!A4,Divisions!B4) -> 134217729
A5: =_xlfn.CEILING.MATH(Divisions!A5,Divisions!B5) -> 150000004
A6: =_xlfn.CEILING.MATH(Divisions!A6,Divisions!B6) -> 1
A7: =_xlfn.CEILING.MATH(Divisions!A7,Divisions!B7) -> 0.3
A8: =_xlfn.CEILING.MATH(Divisions!A8,Divisions!B8) -> 7
A9: =_xlfn.CEILING.MATH(Divisions!A9,Divisions!B9) -> -7
A10: =_xlfn.CEILING.MATH(Divisions!A10,Divisions!B10) -> 7
A11: =_xlfn.CEILING.MATH(Divisions!A11,Divisions!B11) -> 1e+15
A12: =_xlfn.CEILING.MATH(Divisions!A12,Divisions!B12) -> 2.5e+15
... A28: =_xlfn.CEILING.MATH(Divisions!A28,Divisions!B28) -> 11

Sheet FloorMath
A1: =_xlfn.FLOOR.MATH(Divisions!A1,Divisions!B1) -> 9.9
A2: =_xlfn.FLOOR.MATH(Divisions!A2,Divisions!B2) -> 4
A3: =_xlfn.FLOOR.MATH(Divisions!A3,Divisions!B3) -> 9999999999
A4: =_xlfn.FLOOR.MATH(Divisions!A4,Divisions!B4) -> 134217726
A5: =_xlfn.FLOOR.MATH(Divisions!A5,Divisions!B5) -> 149999997
A6: =_xlfn.FLOOR.MATH(Divisions!A6,Divisions!B6) -> 1
A7: =_xlfn.FLOOR.MATH(Divisions!A7,Divisions!B7) -> 0.3
A8: =_xlfn.FLOOR.MATH(Divisions!A8,Divisions!B8) -> 7
A9: =_xlfn.FLOOR.MATH(Divisions!A9,Divisions!B9) -> -7
A10: =_xlfn.FLOOR.MATH(Divisions!A10,Divisions!B10) -> 7
A11: =_xlfn.FLOOR.MATH(Divisions!A11,Divisions!B11) -> 1e+15
A12: =_xlfn.FLOOR.MATH(Divisions!A12,Divisions!B12) -> 2.5e+15
... A28: =_xlfn.FLOOR.MATH(Divisions!A28,Divisions!B28) -> 11

Sheet Hour
A1: =HOUR(Times!A1) -> 12
A2: =HOUR(Times!A2) -> 12
A3: =HOUR(Times!A3) -> 12
A4: =HOUR(Times!A4) -> 11
A5: =HOUR(Times!A5) -> 12
A6: =HOUR(Times!A6) -> 12
A7: =HOUR(Times!A7) -> 18
A8: =HOUR(Times!A8) -> 18
A9: =HOUR(Times!A9) -> 18
A10: =HOUR(Times!A10) -> 17
A11: =HOUR(Times!A11) -> 18
A12: =HOUR(Times!A12) -> 18
... A54: =HOUR(Times!A54) -> 12

Sheet Minute
A1: =MINUTE(Times!A1) -> 0
A2: =MINUTE(Times!A2) -> 0
A3: =MINUTE(Times!A3) -> 0
A4: =MINUTE(Times!A4) -> 59
A5: =MINUTE(Times!A5) -> 0
A6: =MINUTE(Times!A6) -> 0
A7: =MINUTE(Times!A7) -> 0
A8: =MINUTE(Times!A8) -> 0
A9: =MINUTE(Times!A9) -> 0
A10: =MINUTE(Times!A10) -> 59
A11: =MINUTE(Times!A11) -> 0
A12: =MINUTE(Times!A12) -> 0
... A54: =MINUTE(Times!A54) -> 0

Sheet Second
A1: =SECOND(Times!A1) -> 0
A2: =SECOND(Times!A2) -> 0
A3: =SECOND(Times!A3) -> 0
A4: =SECOND(Times!A4) -> 59
A5: =SECOND(Times!A5) -> 0
A6: =SECOND(Times!A6) -> 0
A7: =SECOND(Times!A7) -> 0
A8: =SECOND(Times!A8) -> 0
A9: =SECOND(Times!A9) -> 0
A10: =SECOND(Times!A10) -> 59
A11: =SECOND(Times!A11) -> 0
A12: =SECOND(Times!A12) -> 0
... A54: =SECOND(Times!A54) -> 1

Sheet Days360
A1: =DAYS360(DatePairs!A1,DatePairs!B1) -> 29
A2: =DAYS360(DatePairs!A2,DatePairs!B2) -> 30
A3: =DAYS360(DatePairs!A3,DatePairs!B3) -> 30
A4: =DAYS360(DatePairs!A4,DatePairs!B4) -> 60
A5: =DAYS360(DatePairs!A5,DatePairs!B5) -> 360
A6: =DAYS360(DatePairs!A6,DatePairs!B6) -> 360
A7: =DAYS360(DatePairs!A7,DatePairs!B7) -> 613
A8: =DAYS360(DatePairs!A8,DatePairs!B8) -> 359
A9: =DAYS360(DatePairs!A9,DatePairs!B9) -> 358
A10: =DAYS360(DatePairs!A10,DatePairs!B10) -> 30
A11: =DAYS360(DatePairs!A11,DatePairs!B11) -> 90
A12: =DAYS360(DatePairs!A12,DatePairs!B12) -> 90
... A18: =DAYS360(DatePairs!A18,DatePairs!B18) -> 61

Sheet Days360Europe
A1: =DAYS360(DatePairs!A1,DatePairs!B1,TRUE) -> 29
A2: =DAYS360(DatePairs!A2,DatePairs!B2,TRUE) -> 31
A3: =DAYS360(DatePairs!A3,DatePairs!B3,TRUE) -> 32
A4: =DAYS360(DatePairs!A4,DatePairs!B4,TRUE) -> 60
A5: =DAYS360(DatePairs!A5,DatePairs!B5,TRUE) -> 360
A6: =DAYS360(DatePairs!A6,DatePairs!B6,TRUE) -> 359
A7: =DAYS360(DatePairs!A7,DatePairs!B7,TRUE) -> 613
A8: =DAYS360(DatePairs!A8,DatePairs!B8,TRUE) -> 361
A9: =DAYS360(DatePairs!A9,DatePairs!B9,TRUE) -> 359
A10: =DAYS360(DatePairs!A10,DatePairs!B10,TRUE) -> 32
A11: =DAYS360(DatePairs!A11,DatePairs!B11,TRUE) -> 90
A12: =DAYS360(DatePairs!A12,DatePairs!B12,TRUE) -> 90
... A18: =DAYS360(DatePairs!A18,DatePairs!B18,TRUE) -> 61

Sheet YearFrac0
A1: =YEARFRAC(DatePairs!A1,DatePairs!B1,0) -> 0.080555556
A2: =YEARFRAC(DatePairs!A2,DatePairs!B2,0) -> 0.086111111
A3: =YEARFRAC(DatePairs!A3,DatePairs!B3,0) -> 0.086111111
A4: =YEARFRAC(DatePairs!A4,DatePairs!B4,0) -> 0.16666667
A5: =YEARFRAC(DatePairs!A5,DatePairs!B5,0) -> 1
A6: =YEARFRAC(DatePairs!A6,DatePairs!B6,0) -> 1
A7: =YEARFRAC(DatePairs!A7,DatePairs!B7,0) -> 1.7027778
A8: =YEARFRAC(DatePairs!A8,DatePairs!B8,0) -> 1
A9: =YEARFRAC(DatePairs!A9,DatePairs!B9,0) -> 1
A10: =YEARFRAC(DatePairs!A10,DatePairs!B10,0) -> 0.086111111
A11: =YEARFRAC(DatePairs!A11,DatePairs!B11,0) -> 0.25
A12: =YEARFRAC(DatePairs!A12,DatePairs!B12,0) -> 0.25
... A18: =YEARFRAC(DatePairs!A18,DatePairs!B18,0) -> 0.16944444

Sheet YearFrac1
A1: =YEARFRAC(DatePairs!A1,DatePairs!B1,1) -> 0.079234973
A2: =YEARFRAC(DatePairs!A2,DatePairs!B2,1) -> 0.084699454
A3: =YEARFRAC(DatePairs!A3,DatePairs!B3,1) -> 0.084931507
A4: =YEARFRAC(DatePairs!A4,DatePairs!B4,1) -> 0.16666667
A5: =YEARFRAC(DatePairs!A5,DatePairs!B5,1) -> 0.99726027
A6: =YEARFRAC(DatePairs!A6,DatePairs!B6,1) -> 0.99726776
A7: =YEARFRAC(DatePairs!A7,DatePairs!B7,1) -> 1.7080292
A8: =YEARFRAC(DatePairs!A8,DatePairs!B8,1) -> 1.001368
A9: =YEARFRAC(DatePairs!A9,DatePairs!B9,1) -> 0.99726776
A10: =YEARFRAC(DatePairs!A10,DatePairs!B10,1) -> 0.084931507
A11: =YEARFRAC(DatePairs!A11,DatePairs!B11,1) -> 0.25136612
A12: =YEARFRAC(DatePairs!A12,DatePairs!B12,1) -> 0.25409836
... A18: =YEARFRAC(DatePairs!A18,DatePairs!B18,1) -> 0.16666667

Sheet YearFrac2
A1: =YEARFRAC(DatePairs!A1,DatePairs!B1,2) -> 0.080555556
A2: =YEARFRAC(DatePairs!A2,DatePairs!B2,2) -> 0.086111111
A3: =YEARFRAC(DatePairs!A3,DatePairs!B3,2) -> 0.086111111
A4: =YEARFRAC(DatePairs!A4,DatePairs!B4,2) -> 0.16944444
A5: =YEARFRAC(DatePairs!A5,DatePairs!B5,2) -> 1.0111111
A6: =YEARFRAC(DatePairs!A6,DatePairs!B6,2) -> 1.0138889
A7: =YEARFRAC(DatePairs!A7,DatePairs!B7,2) -> 1.7333333
A8: =YEARFRAC(DatePairs!A8,DatePairs!B8,2) -> 1.0166667
A9: =YEARFRAC(DatePairs!A9,DatePairs!B9,2) -> 1.0138889
A10: =YEARFRAC(DatePairs!A10,DatePairs!B10,2) -> 0.086111111
A11: =YEARFRAC(DatePairs!A11,DatePairs!B11,2) -> 0.25555556
A12: =YEARFRAC(DatePairs!A12,DatePairs!B12,2) -> 0.25833333
... A18: =YEARFRAC(DatePairs!A18,DatePairs!B18,2) -> 0.16944444

Sheet YearFrac3
A1: =YEARFRAC(DatePairs!A1,DatePairs!B1,3) -> 0.079452055
A2: =YEARFRAC(DatePairs!A2,DatePairs!B2,3) -> 0.084931507
A3: =YEARFRAC(DatePairs!A3,DatePairs!B3,3) -> 0.084931507
A4: =YEARFRAC(DatePairs!A4,DatePairs!B4,3) -> 0.16712329
A5: =YEARFRAC(DatePairs!A5,DatePairs!B5,3) -> 0.99726027
A6: =YEARFRAC(DatePairs!A6,DatePairs!B6,3) -> 1
A7: =YEARFRAC(DatePairs!A7,DatePairs!B7,3) -> 1.709589
A8: =YEARFRAC(DatePairs!A8,DatePairs!B8,3) -> 1.0027397
A9: =YEARFRAC(DatePairs!A9,DatePairs!B9,3) -> 1
A10: =YEARFRAC(DatePairs!A10,DatePairs!B10,3) -> 0.084931507
A11: =YEARFRAC(DatePairs!A11,DatePairs!B11,3) -> 0.25205479
A12: =YEARFRAC(DatePairs!A12,DatePairs!B12,3) -> 0.25479452
... A18: =YEARFRAC(DatePairs!A18,DatePairs!B18,3) -> 0.16712329

Sheet YearFrac4
A1: =YEARFRAC(DatePairs!A1,DatePairs!B1,4) -> 0.080555556
A2: =YEARFRAC(DatePairs!A2,DatePairs!B2,4) -> 0.086111111
A3: =YEARFRAC(DatePairs!A3,DatePairs!B3,4) -> 0.088888889
A4: =YEARFRAC(DatePairs!A4,DatePairs!B4,4) -> 0.16666667
A5: =YEARFRAC(DatePairs!A5,DatePairs!B5,4) -> 1
A6: =YEARFRAC(DatePairs!A6,DatePairs!B6,4) -> 0.99722222
A7: =YEARFRAC(DatePairs!A7,DatePairs!B7,4) -> 1.7027778
A8: =YEARFRAC(DatePairs!A8,DatePairs!B8,4) -> 1.0027778
A9: =YEARFRAC(DatePairs!A9,DatePairs!B9,4) -> 0.99722222
A10: =YEARFRAC(DatePairs!A10,DatePairs!B10,4) -> 0.088888889
A11: =YEARFRAC(DatePairs!A11,DatePairs!B11,4) -> 0.25
A12: =YEARFRAC(DatePairs!A12,DatePairs!B12,4) -> 0.25
... A18: =YEARFRAC(DatePairs!A18,DatePairs!B18,4) -> 0.16944444

Sheet CountIf
A1: =COUNTIF(Crit!A1:A30,"") -> 2
A2: =COUNTIF(Crit!A1:A30,"=") -> 1
A3: =COUNTIF(Crit!A1:A30,"<>") -> 29
A4: =COUNTIF(Crit!A1:A30,"=10") -> 4
A5: =COUNTIF(Crit!A1:A30,"10") -> 4
A6: =COUNTIF(Crit!A1:A30,10) -> 4
A7: =COUNTIF(Crit!A1:A30,">5") -> 3
A8: =COUNTIF(Crit!A1:A30,"<5") -> 3
A9: =COUNTIF(Crit!A1:A30,">=10") -> 3
A10: =COUNTIF(Crit!A1:A30,"<>10") -> 29
A11: =COUNTIF(Crit!A1:A30,"a*") -> 5
A12: =COUNTIF(Crit!A1:A30,"*") -> 19
A13: =COUNTIF(Crit!A1:A30,"?") -> 6
A14: =COUNTIF(Crit!A1:A30,"ß") -> 3
A15: =COUNTIF(Crit!A1:A30,"SS") -> 3
A16: =COUNTIF(Crit!A1:A30,"æ") -> 2
A17: =COUNTIF(Crit!A1:A30,"ae") -> 2
A18: =COUNTIF(Crit!A1:A30,"é") -> 1
A19: =COUNTIF(Crit!A1:A30,"e") -> 1
A20: =COUNTIF(Crit!A1:A30,TRUE) -> 1
A21: =COUNTIF(Crit!A1:A30,"TRUE") -> 1
A22: =COUNTIF(Crit!A1:A30,"#N/A") -> 1
A23: =COUNTIF(Crit!A1:A30,"<>#N/A") -> 29
A24: =COUNTIF(Crit!A1:A30,">a") -> 12
A25: =COUNTIF(Crit!A1:A30,"<z") -> 19
A26: =COUNTIF(Crit!A1:A30,"1/2/2020") -> 3
A27: =COUNTIF(Crit!A1:A30,">1/1/2020") -> 2
A28: =COUNTIF(Crit!A1:A30,"12:00") -> 1
A29: =COUNTIF(Crit!A1:A30," 10") -> 4
A30: =COUNTIF(Crit!A1:A30,"10 ") -> 4
A31: =COUNTIF(Crit!A1:A30,"~*") -> 1
A32: =COUNTIF(Crit!A1:A30,"=a*e") -> 4
A33: =COUNTIF(Crit!A1:A30,"<>abc") -> 29
A34: =COUNTIF(Crit!A1:A30,Crit!D1) -> 1
A35: =COUNTIF(Crit!A1:A30,"=5") -> 2
A36: =COUNTIF(Crit!A1:A30,">4.5") -> 4
A37: =COUNTIF(Crit!A1:A30,"<>5") -> 29

Sheet SumIf
A1: =SUMIF(Crit!A1:A30,"",Crit!B1:B30) -> 37
A2: =SUMIF(Crit!A1:A30,"=",Crit!B1:B30) -> 19
A3: =SUMIF(Crit!A1:A30,"<>",Crit!B1:B30) -> 446
A4: =SUMIF(Crit!A1:A30,"=10",Crit!B1:B30) -> 32
A5: =SUMIF(Crit!A1:A30,"10",Crit!B1:B30) -> 32
A6: =SUMIF(Crit!A1:A30,10,Crit!B1:B30) -> 32
A7: =SUMIF(Crit!A1:A30,">5",Crit!B1:B30) -> 46
A8: =SUMIF(Crit!A1:A30,"<5",Crit!B1:B30) -> 84
A9: =SUMIF(Crit!A1:A30,">=10",Crit!B1:B30) -> 46
A10: =SUMIF(Crit!A1:A30,"<>10",Crit!B1:B30) -> 464
A11: =SUMIF(Crit!A1:A30,"a*",Crit!B1:B30) -> 51
A12: =SUMIF(Crit!A1:A30,"*",Crit!B1:B30) -> 250
A13: =SUMIF(Crit!A1:A30,"?",Crit!B1:B30) -> 87
A14: =SUMIF(Crit!A1:A30,"ß",Crit!B1:B30) -> 24
A15: =SUMIF(Crit!A1:A30,"SS",Crit!B1:B30) -> 24
A16: =SUMIF(Crit!A1:A30,"æ",Crit!B1:B30) -> 21
A17: =SUMIF(Crit!A1:A30,"ae",Crit!B1:B30) -> 21
A18: =SUMIF(Crit!A1:A30,"é",Crit!B1:B30) -> 12
A19: =SUMIF(Crit!A1:A30,"e",Crit!B1:B30) -> 13
A20: =SUMIF(Crit!A1:A30,TRUE,Crit!B1:B30) -> 14
A21: =SUMIF(Crit!A1:A30,"TRUE",Crit!B1:B30) -> 14
A22: =SUMIF(Crit!A1:A30,"#N/A",Crit!B1:B30) -> 17
A23: =SUMIF(Crit!A1:A30,"<>#N/A",Crit!B1:B30) -> 448
A24: =SUMIF(Crit!A1:A30,">a",Crit!B1:B30) -> 126
A25: =SUMIF(Crit!A1:A30,"<z",Crit!B1:B30) -> 250
A26: =SUMIF(Crit!A1:A30,"1/2/2020",Crit!B1:B30) -> 75
A27: =SUMIF(Crit!A1:A30,">1/1/2020",Crit!B1:B30) -> 45
A28: =SUMIF(Crit!A1:A30,"12:00",Crit!B1:B30) -> 29
A29: =SUMIF(Crit!A1:A30," 10",Crit!B1:B30) -> 32
A30: =SUMIF(Crit!A1:A30,"10 ",Crit!B1:B30) -> 32
A31: =SUMIF(Crit!A1:A30,"~*",Crit!B1:B30) -> 24
A32: =SUMIF(Crit!A1:A30,"=a*e",Crit!B1:B30) -> 47
A33: =SUMIF(Crit!A1:A30,"<>abc",Crit!B1:B30) -> 461
A34: =SUMIF(Crit!A1:A30,Crit!D1,Crit!B1:B30) -> 27
A35: =SUMIF(Crit!A1:A30,"=5",Crit!B1:B30) -> 41
A36: =SUMIF(Crit!A1:A30,">4.5",Crit!B1:B30) -> 66
A37: =SUMIF(Crit!A1:A30,"<>5",Crit!B1:B30) -> 445

Sheet ValueLong
A1: =VALUE("1.23456789012345678") -> 1.2345679
A2: =VALUE("2.9999999999999996") -> 3
A3: =VALUE("1e-308") -> 0
A4: =VALUE("1e-307") -> 1e-307
A5: =VALUE("2.2250738585072014e-308") -> 0
A6: =VALUE("9.99999999999999e307") -> 1e+308
A7: =VALUE("9.999999999999995e307") -> 1e+308
A8: =VALUE("1234567890123456789") -> 1.2345679e+18
A9: =VALUE("0.30000000000000004") -> 0.3
A10: ="1.23456789012345678"+0 -> 1.2345679
A11: ="12345678901234567"+0 -> 1.2345679e+16
A12: =VALUE("1.5e-308") -> 0

Sheet Lookups2
A1: =MATCH(Crit!D1,Crit!A1:A30,0) -> 27
A2: =VLOOKUP(10,Crit!A1:B30,2,FALSE) -> 1
A3: =VLOOKUP("10",Crit!A1:B30,2,FALSE) -> 2
A4: =MATCH("a?e",Crit!A1:A30,0) -> 25
A5: =MATCH(5,{1,3,5,7},1) -> 3
